Workbook

Sheet 2025
B1: JAN | C1: FEB | D1: MAR | E1: APR | F1: MAY | G1: JUN | H1: JUL | I1: AUG | J1: SEP | K1: OCT | L1: NOV | M1: DEC
A2: Common Room | B2: 149718 | C2: 100378 | D2: 110821 | E2: 96858 | F2: 120151 | G2: 132070 | H2: 124470 | I2: 117003 | J2: 112778 | K2: 102137 | L2: 136158 | M2: 391157 | O2: =SUM(B2:F2) -> 577926
A3: Frankie and Friends | B3: 107838 | C3: 35082 | D3: 53097 | E3: 31058 | F3: 52598 | G3: 44813 | H3: 31878 | I3: 38896 | J3: 51940 | K3: 27723 | L3: 68281 | M3: 206238 | O3: =SUM(B3:F3) -> 279673
A4: Craft Central | B4: 8415 | C4: 7547 | D4: 5301 | E4: 5623 | F4: 5343 | G4: 7937 | H4: 4706 | I4: 7705 | J4: 5653 | K4: 5653 | L4: 14587 | M4: 14305 | O4: =SUM(B4:F4) -> 32229
A5: Simula PH | B5: 8467 | C5: 6562 | D5: 6031 | E5: 7311 | F5: 9553 | G5: 4666 | H5: 6122 | I5: 11018 | J5: 7879 | K5: 8069 | L5: 17564 | M5: 18081 | O5: =SUM(B5:F5) -> 37924
A6: 9 Matters | B6: 4117 | C6: 5120 | D6: 2503 | E6: 1817 | F6: 4742 | G6: 5576 | H6: 2115 | I6: 1786 | J6: 4457 | K6: 5587 | L6: 6025 | M6: 7940 | O6: =SUM(B6:F6) -> 18299
A7: Lazada | B7: 37084 | C7: 10641 | D7: 25587 | E7: 25036 | F7: 33962 | G7: 19743 | H7: 26690 | I7: 33401 | J7: 36353 | K7: 16025 | L7: 48918 | M7: 27482 | O7: =SUM(B7:F7) -> 132310
A8: Shopee | B8: 42302 | C8: 35262 | D8: 36184 | E8: 35911 | F8: 37121 | G8: 45294 | H8: 44055 | I8: 77103 | J8: 82374 | K8: 63142 | L8: 104195 | M8: 179518 | O8: =SUM(B8:F8) -> 186780
A9: Shopify | B9: 38603 | C9: 73396 | D9: 29005 | E9: 57156 | F9: 31154 | G9: 45210 | H9: 16551 | I9: 75906 | J9: 11261 | K9: 47911 | L9: 68469 | M9: 267089 | O9: =SUM(B9:F9) -> 229314
A10: Pick-a-roo | B10: 1128 | C10: 0 | E10: 0 | F10: 0 | G10: 878 | O10: =SUM(B10:F10) -> 1128
A11: Tiktok | B11: 2035 | C11: 1547 | D11: 2523 | E11: 609 | F11: 329 | G11: 0 | H11: 329 | I11: 3889 | J11: 5646 | K11: 1576 | L11: 5546 | M11: 1128
A12: World Plaza | B12: 11524.8 | C12: 11524.8 | D12: 11524.8 | E12: 11524.8 | F12: 11524.8 | G12: 11524.8 | H12: 11524.8 | I12: 11524.8 | J12: 11524.8 | K12: 11524.8 | L12: 11524.8 | M12: 11524.8
A13: The Finance | B13: 25000 | C13: 27500 | D13: 27500 | E13: 27500 | G13: 27500 | H13: 27500 | I13: 35000 | J13: 35000 | K13: 35000 | L13: 35000 | M13: 35000
A14: Seibu | B14: 12000 | C14: 12000 | D14: 12000 | E14: 12000 | F14: 12000 | G14: 12000 | H14: 12000 | I14: 12000 | J14: 12000 | K14: 12000 | L14: 12000 | M14: 12000
A15: Grasshopper Concept | B15: 6000
A16: Haleon | H16: 11000 | I16: 11000 | J16: 11000 | K16: 11000 | L16: 11000 | M16: 11000
A17: Bazaar | M17: 310150
A20: TOTAL | B20: 454231.8 | C20: 326559.8 | D20: 322076.8 | E20: 312403.8 | F20: 318477.8 | G20: 357211.8 | H20: 307940.8 | I20: 436231.8 | J20: 387865.8 | K20: 347347.8 | L20: 539267.8

Sheet ACCOUNT PERFORMANCE
B1: % cont | C1: 45659 | D1: Target | F1: vs PY | H1: % cont | I1: JAN YTD | J1: PY | K1: vs PY | L1: % cont | M1: 46060 | N1: Target | P1: vs PY | R1: % cont | S1: FEB YTD | T1: PY | U1: vs PY | V1: % cont | W1: 46093 | X1: Target | Z1: vs PY | AB1: % cont | AC1: MAR YTD | AD1: PY | AE1: vs PY | AF1: % cont | AG1: 46115 | AH1: Target | AJ1: vs PY | AL1: % cont | AM1: APR YTD | AN1: PY | AO1: vs PY | AP1: % cont | AQ1: 46161 | AR1: Target | AT1: vs PY | AV1: % cont | AW1: MAY YTD | AX1: PY | AY1: vs PY
A2: Common Room | B2: =C2/$C$20 -> 0.30944554 | C2: ='COMMONROOM SUMMARY'!Q102 -> 146221 | D2: 146832 | F2: =sum(C2-E2)/E2 -> #DIV/0! | H2: =I2/$I$20 -> 0.3539382 | I2: =C2 -> 146221 | J2: 149718 | K2: =sum(I2-J2)/J2 -> -0.023357245 | L2: =M2/$C$20 -> 0.20241011 | M2: ='COMMONROOM SUMMARY'!R102 -> 95644 | N2: 146832 | P2: =sum(M2-O2)/O2 -> #DIV/0! | R2: =S2/$I$20 -> 0.58545121 | S2: =I2+M2 -> 241865 | T2: ='2025'!B2+'2025'!C2 -> 250096 | U2: =sum(S2-T2)/T2 -> -0.032911362 | V2: =W2/$C$20 -> 0.17275247 | W2: ='COMMONROOM SUMMARY'!S102 -> 81630 | X2: 146832 | Z2: =sum(W2-Y2)/Y2 -> #DIV/0! | AB2: =AC2/$I$20 -> 0.78304236 | AC2: =S2+W2 -> 323495 | AD2: =SUM('2025'!B2:D2) -> 360917 | AE2: =sum(AC2-AD2)/AD2 -> -0.10368589 | AF2: =AG2/$C$20 -> 0.20396347 | AG2: ='COMMONROOM SUMMARY'!T102 -> 96378 | AH2: 146832 | AJ2: =sum(AG2-AI2)/AI2 -> #DIV/0! | AL2: =AM2/$I$20 -> 1.0163321 | AM2: =AC2+AG2 -> 419873 | AN2: =SUM('2025'!B2:E2) -> 457775 | AO2: =sum(AM2-AN2)/AN2 -> -0.082796133 | AP2: =AQ2/$C$20 -> 0 | AR2: 146832 | AT2: =sum(AQ2-AS2)/AS2 -> #DIV/0! | AV2: =AW2/$I$20 -> 1.0163321 | AW2: =AM2+AQ2 -> 419873 | AX2: =SUM('2025'!B2:F2) -> 577926 | AY2: =sum(AW2-AX2)/AX2 -> -0.27348311
A3: Frankie and Friends | B3: =C3/$C$20 -> 0.092634095 | C3: =FRANKIE!A111 -> 43772 | D3: 64977 | F3: =sum(C3-E3)/E3 -> #DIV/0! | H3: =I3/$I$20 -> 0.1059532 | I3: =C3 -> 43772 | J3: 107838 | K3: =sum(I3-J3)/J3 -> -0.59409485 | L3: =M3/$C$20 -> 0.092634095 | M3: ='FRANKIE SUMMARY'!Q102 -> 43772 | N3: 64977 | P3: =sum(M3-O3)/O3 -> #DIV/0! | R3: =S3/$I$20 -> 0.2119064 | S3: =I3+M3 -> 87544 | T3: ='2025'!B3+'2025'!C3 -> 142920 | U3: =sum(S3-T3)/T3 -> -0.38746152 | V3: =W3/$C$20 -> 0.056858271 | W3: ='FRANKIE SUMMARY'!R102 -> 26867 | X3: 64977 | Z3: =sum(W3-Y3)/Y3 -> #DIV/0! | AB3: =AC3/$I$20 -> 0.27693986 | AC3: =S3+W3 -> 114411 | AD3: =SUM('2025'!B3:D3) -> 196017 | AE3: =sum(AC3-AD3)/AD3 -> -0.41632103 | AF3: =AG3/$C$20 -> 0.055715476 | AG3: ='FRANKIE SUMMARY'!T102 -> 26327 | AH3: 64977 | AJ3: =sum(AG3-AI3)/AI3 -> #DIV/0! | AL3: =AM3/$I$20 -> 0.34066621 | AM3: =AC3+AG3 -> 140738 | AN3: =SUM('2025'!B3:E3) -> 227075 | AO3: =sum(AM3-AN3)/AN3 -> -0.38021359 | AP3: =AQ3/$C$20 -> 0 | AQ3: =FRANKIE!AE112 | AR3: 64977 | AT3: =sum(AQ3-AS3)/AS3 -> #DIV/0! | AV3: =AW3/$I$20 -> 0.34066621 | AW3: =AM3+AQ3 -> 140738 | AX3: =SUM('2025'!B3:F3) -> 279673 | AY3: =sum(AW3-AX3)/AX3 -> -0.49677659
A4: Craft Central | B4: =C4/$C$20 -> 0.011349645 | C4: =TCC!C99 -> 5363 | D4: 7975 | F4: =sum(C4-E4)/E4 -> #DIV/0! | H4: =I4/$I$20 -> 0.012981518 | I4: =C4 -> 5363 | J4: 8415 | K4: =sum(I4-J4)/J4 -> -0.36268568 | L4: =M4/$C$20 -> 0.0061710916 | M4: =TCC!A109 -> 2916 | N4: 7975 | P4: =sum(M4-O4)/O4 -> #DIV/0! | R4: =S4/$I$20 -> 0.020039901 | S4: =I4+M4 -> 8279 | T4: ='2025'!B4+'2025'!C4 -> 15962 | U4: =sum(S4-T4)/T4 -> -0.48133066 | V4: =W4/$C$20 -> 0.0061710916 | W4: ='TCC SUMMARY'!R102 -> 2916 | X4: 7975 | Z4: =sum(W4-Y4)/Y4 -> #DIV/0! | AB4: =AC4/$I$20 -> 0.027098283 | AC4: =S4+W4 -> 11195 | AD4: =SUM('2025'!B4:D4) -> 21263 | AE4: =sum(AC4-AD4)/AD4 -> -0.47349857 | AF4: =AG4/$C$20 -> 0 | AG4: ='TCC SUMMARY'!T102 | AH4: 7975 | AJ4: =sum(AG4-AI4)/AI4 -> #DIV/0! | AL4: =AM4/$I$20 -> 0.027098283 | AM4: =AC4+AG4 -> 11195 | AN4: =SUM('2025'!B4:E4) -> 26886 | AO4: =sum(AM4-AN4)/AN4 -> -0.58361229 | AP4: =AQ4/$C$20 -> 0 | AQ4: =TCC!AE109 | AR4: 7975 | AT4: =sum(AQ4-AS4)/AS4 -> #DIV/0! | AV4: =AW4/$I$20 -> 0.027098283 | AW4: =AM4+AQ4 -> 11195 | AX4: =SUM('2025'!B4:F4) -> 32229 | AY4: =sum(AW4-AX4)/AX4 -> -0.65264203
A5: Simula PH | B5: =C5/$C$20 -> 0.0210634 | C5: =SIMULAPH!C102 -> 9953 | D5: 7563 | F5: =sum(C5-E5)/E5 -> #DIV/0! | H5: =I5/$I$20 -> 0.024091935 | I5: =C5 -> 9953 | J5: 8467 | K5: =sum(I5-J5)/J5 -> 0.1755049 | L5: =M5/$C$20 -> 0.010088338 | M5: ='SIMULAPH SUMMARY'!R102 -> 4767 | N5: 7563 | P5: =sum(M5-O5)/O5 -> #DIV/0! | R5: =S5/$I$20 -> 0.035630793 | S5: =I5+M5 -> 14720 | T5: ='2025'!B5+'2025'!C5 -> 15029 | U5: =sum(S5-T5)/T5 -> -0.02056025 | V5: =W5/$C$20 -> 0.010088338 | W5: ='SIMULAPH SUMMARY'!R102 -> 4767 | X5: 7563 | Z5: =sum(W5-Y5)/Y5 -> #DIV/0! | AB5: =AC5/$I$20 -> 0.047169651 | AC5: =S5+W5 -> 19487 | AD5: =SUM('2025'!B5:D5) -> 21060 | AE5: =sum(AC5-AD5)/AD5 -> -0.074691358 | AF5: =AG5/$C$20 -> 0.010975062 | AG5: ='SIMULAPH SUMMARY'!T102 -> 5186 | AH5: 7563 | AJ5: =sum(AG5-AI5)/AI5 -> #DIV/0! | AL5: =AM5/$I$20 -> 0.059722729 | AM5: =AC5+AG5 -> 24673 | AN5: =SUM('2025'!B5:E5) -> 28371 | AO5: =sum(AM5-AN5)/AN5 -> -0.13034437 | AP5: =AQ5/$C$20 -> 0 | AR5: 7563 | AT5: =sum(AQ5-AS5)/AS5 -> #DIV/0! | AV5: =AW5/$I$20 -> 0.059722729 | AW5: =AM5+AQ5 -> 24673 | AX5: =SUM('2025'!B5:F5) -> 37924 | AY5: =sum(AW5-AX5)/AX5 -> -0.34940934
A6: 9 Matters | B6: =C6/$C$20 -> 0.0098534302 | C6: ='9 Matters'!C99 -> 4656 | D6: 9864 | F6: =sum(C6-E6)/E6 -> #DIV/0! | H6: =I6/$I$20 -> 0.011270175 | I6: =C6 -> 4656 | J6: 4117 | K6: =sum(I6-J6)/J6 -> 0.13092057 | L6: =M6/$C$20 -> 0.031805671 | M6: ='9MATTERS SUMMARY'!R102 -> 15029 | N6: 9864 | P6: =sum(M6-O6)/O6 -> #DIV/0! | R6: =S6/$I$20 -> 0.047648924 | S6: =I6+M6 -> 19685 | T6: ='2025'!B6+'2025'!C6 -> 9237 | U6: =sum(S6-T6)/T6 -> 1.1311032 | V6: =W6/$C$20 -> 0.046259908 | W6: ='9MATTERS SUMMARY'!S102 -> 21859 | X6: 9864 | Z6: =sum(W6-Y6)/Y6 -> #DIV/0! | AB6: =AC6/$I$20 -> 0.10056017 | AC6: =S6+W6 -> 41544 | AD6: =SUM('2025'!B6:D6) -> 11740 | AE6: =sum(AC6-AD6)/AD6 -> 2.5386712 | AF6: =AG6/$C$20 -> 0.011087225 | AG6: ='9MATTERS SUMMARY'!T102 -> 5239 | AH6: 9864 | AJ6: =sum(AG6-AI6)/AI6 -> #DIV/0! | AL6: =AM6/$I$20 -> 0.11324154 | AM6: =AC6+AG6 -> 46783 | AN6: =SUM('2025'!B6:E6) -> 13557 | AO6: =sum(AM6-AN6)/AN6 -> 2.4508372 | AP6: =AQ6/$C$20 -> 0 | AR6: 9864 | AT6: =sum(AQ6-AS6)/AS6 -> #DIV/0! | AV6: =AW6/$I$20 -> 0.11324154 | AW6: =AM6+AQ6 -> 46783 | AX6: =SUM('2025'!B6:F6) -> 18299 | AY6: =sum(AW6-AX6)/AX6 -> 1.5565878
A7: Lazada | B7: =C7/$C$20 -> 0.036539804 | C7: =LAZADA!A111 -> 17266 | D7: 47694 | F7: =sum(C7-E7)/E7 -> #DIV/0! | H7: =I7/$I$20 -> 0.041793565 | I7: =C7 -> 17266 | J7: 37084 | K7: =sum(I7-J7)/J7 -> -0.53440837 | L7: =M7/$C$20 -> 0.052524116 | M7: =LAZADA!A112 -> 24819 | N7: 47694 | P7: =sum(M7-O7)/O7 -> #DIV/0! | R7: =S7/$I$20 -> 0.1018697 | S7: =I7+M7 -> 42085 | T7: ='2025'!B7+'2025'!C7 -> 47725 | U7: =sum(S7-T7)/T7 -> -0.11817706 | V7: =W7/$C$20 -> 0.036463617 | W7: =LAZADA!A113 -> 17230 | X7: 47694 | Z7: =sum(W7-Y7)/Y7 -> #DIV/0! | AB7: =AC7/$I$20 -> 0.14357612 | AC7: =S7+W7 -> 59315 | AD7: =SUM('2025'!B7:D7) -> 73312 | AE7: =sum(AC7-AD7)/AD7 -> -0.19092372 | AF7: =AG7/$C$20 -> 0.062874874 | AG7: =LAZADA!A114 -> 29710 | AH7: 47694 | AJ7: =sum(AG7-AI7)/AI7 -> #DIV/0! | AL7: =AM7/$I$20 -> 0.21549126 | AM7: =AC7+AG7 -> 89025 | AN7: =SUM('2025'!B7:E7) -> 98348 | AO7: =sum(AM7-AN7)/AN7 -> -0.09479603 | AP7: =AQ7/$C$20 -> 0.042882315 | AQ7: =LAZADA!A115 -> 20263 | AR7: 47694 | AT7: =sum(AQ7-AS7)/AS7 -> #DIV/0! | AV7: =AW7/$I$20 -> 0.26453928 | AW7: =AM7+AQ7 -> 109288 | AX7: =SUM('2025'!B7:F7) -> 132310 | AY7: =sum(AW7-AX7)/AX7 -> -0.17400045
A8: Shopee | B8: =C8/$C$20 -> 0.11779463 | C8: =SHOPEE!A112 -> 55661 | D8: 66493 | F8: =sum(C8-E8)/E8 -> #DIV/0! | H8: =I8/$I$20 -> 0.13473136 | I8: =C8 -> 55661 | J8: 42302 | K8: =sum(I8-J8)/J8 -> 0.31580067 | L8: =M8/$C$20 -> 0.07204686 | M8: =SHOPEE!A113 -> 34044 | N8: 66493 | P8: =sum(M8-O8)/O8 -> #DIV/0! | R8: =S8/$I$20 -> 0.21713725 | S8: =I8+M8 -> 89705 | T8: ='2025'!B8+'2025'!C8 -> 77564 | U8: =sum(S8-T8)/T8 -> 0.1565288 | V8: =W8/$C$20 -> 0.069699898 | W8: =SHOPEE!A114 -> 32935 | X8: 66493 | Z8: =sum(W8-Y8)/Y8 -> #DIV/0! | AB8: =AC8/$I$20 -> 0.29685873 | AC8: =S8+W8 -> 122640 | AD8: =SUM('2025'!B8:D8) -> 113748 | AE8: =sum(AC8-AD8)/AD8 -> 0.078172803 | AF8: =AG8/$C$20 -> 0.073117701 | AG8: =SHOPEE!A115 -> 34550 | AH8: 66493 | AJ8: =sum(AG8-AI8)/AI8 -> #DIV/0! | AL8: =AM8/$I$20 -> 0.38048943 | AM8: =AC8+AG8 -> 157190 | AN8: =SUM('2025'!B8:E8) -> 149659 | AO8: =sum(AM8-AN8)/AN8 -> 0.050321063 | AP8: =AQ8/$C$20 -> 0.064779532 | AQ8: =SHOPEE!A116 -> 30610 | AR8: 66493 | AT8: =sum(AQ8-AS8)/AS8 -> #DIV/0! | AV8: =AW8/$I$20 -> 0.45458308 | AW8: =AM8+AQ8 -> 187800 | AX8: =SUM('2025'!B8:F8) -> 186780 | AY8: =sum(AW8-AX8)/AX8 -> 0.0054609701
A9: Shopify | B9: =C9/$C$20 -> 0.017728133 | C9: =SHOPIFY!A111 -> 8377 | D9: 92744 | F9: =sum(C9-E9)/E9 -> #DIV/0! | H9: =I9/$I$20 -> 0.020277117 | I9: =C9 -> 8377 | J9: 38603 | K9: =sum(I9-J9)/J9 -> -0.78299614 | L9: =M9/$C$20 -> 0.049444919 | M9: =SHOPIFY!A112 -> 23364 | N9: 92744 | P9: =sum(M9-O9)/O9 -> #DIV/0! | R9: =S9/$I$20 -> 0.076831319 | S9: =I9+M9 -> 31741 | T9: ='2025'!B9+'2025'!C9 -> 111999 | U9: =sum(S9-T9)/T9 -> -0.71659568 | V9: =W9/$C$20 -> 0.069244896 | W9: =SHOPIFY!A113 -> 32720 | X9: 92744 | Z9: =sum(W9-Y9)/Y9 -> #DIV/0! | AB9: =AC9/$I$20 -> 0.15603238 | AC9: =S9+W9 -> 64461 | AD9: =SUM('2025'!B9:D9) -> 141004 | AE9: =sum(AC9-AD9)/AD9 -> -0.54284276 | AF9: =AG9/$C$20 -> 0.073919773 | AG9: =SHOPIFY!A114 -> 34929 | AH9: 92744 | AJ9: =sum(AG9-AI9)/AI9 -> #DIV/0! | AL9: =AM9/$I$20 -> 0.24058047 | AM9: =AC9+AG9 -> 99390 | AN9: =SUM('2025'!B9:E9) -> 198160 | AO9: =sum(AM9-AN9)/AN9 -> -0.49843561 | AP9: =AQ9/$C$20 -> 0.059838003 | AQ9: =SHOPIFY!A115 -> 28275 | AR9: 92744 | AT9: =sum(AQ9-AS9)/AS9 -> #DIV/0! | AV9: =AW9/$I$20 -> 0.30902209 | AW9: =AM9+AQ9 -> 127665 | AX9: =SUM('2025'!B9:F9) -> 229314 | AY9: =sum(AW9-AX9)/AX9 -> -0.44327429
A10: Pick-a-roo | B10: =C10/$C$20 -> 0 | D10: 689 | F10: =sum(C10-E10)/E10 -> #DIV/0! | H10: =I10/$I$20 -> 0 | I10: =C10 | J10: 1128 | K10: =sum(I10-J10)/J10 -> -1 | L10: =M10/$C$20 -> 0 | M10: =PICKAROO!A109 | N10: 689 | P10: =sum(M10-O10)/O10 -> #DIV/0! | R10: =S10/$I$20 -> 0 | S10: =I10+M10 -> 0 | T10: ='2025'!B10+'2025'!C10 -> 1128 | U10: =sum(S10-T10)/T10 -> -1 | V10: =W10/$C$20 -> 0 | X10: 689 | Z10: =sum(W10-Y10)/Y10 -> #DIV/0! | AB10: =AC10/$I$20 -> 0 | AC10: =S10+W10 -> 0 | AD10: =SUM('2025'!B10:D10) -> 1128 | AE10: =sum(AC10-AD10)/AD10 -> -1 | AF10: =AG10/$C$20 -> 0 | AH10: 689 | AJ10: =sum(AG10-AI10)/AI10 -> #DIV/0! | AL10: =AM10/$I$20 -> 0 | AM10: =AC10+AG10 -> 0 | AN10: =SUM('2025'!B10:E10) -> 1128 | AO10: =sum(AM10-AN10)/AN10 -> -1 | AP10: =AQ10/$C$20 -> 0 | AR10: 689 | AT10: =sum(AQ10-AS10)/AS10 -> #DIV/0! | AV10: =AW10/$I$20 -> 0 | AW10: =AM10+AQ10 -> 0 | AX10: =SUM('2025'!B10:F10) -> 1128 | AY10: =sum(AW10-AX10)/AX10 -> -1
A11: Tiktok | B11: =C11/$C$20 -> 0.0051087158 | C11: =TIKTOK!A108 -> 2414 | D11: 689 | F11: =sum(C11-E11)/E11 -> #DIV/0! | H11: =I11/$I$20 -> 0.0058432565 | I11: =C11 -> 2414 | J11: 2035 | K11: =sum(I11-J11)/J11 -> 0.18624079 | L11: =M11/$C$20 -> 0.0088206824 | M11: =TIKTOK!A109 -> 4168 | N11: 689 | P11: =sum(M11-O11)/O11 -> #DIV/0! | R11: =S11/$I$20 -> 0.015932193 | S11: =I11+M11 -> 6582 | T11: ='2025'!B11+'2025'!C11 -> 3582 | U11: =sum(S11-T11)/T11 -> 0.83752094 | V11: =W11/$C$20 -> 0.017979971 | W11: =TIKTOK!A110 -> 8496 | X11: 689 | Z11: =sum(W11-Y11)/Y11 -> #DIV/0! | AB11: =AC11/$I$20 -> 0.036497357 | AC11: =S11+W11 -> 15078 | AD11: =SUM('2025'!B11:D11) -> 6105 | AE11: =sum(AC11-AD11)/AD11 -> 1.4697789 | AF11: =AG11/$C$20 -> 0.027499028 | AG11: =TIKTOK!A111 -> 12994 | AH11: 689 | AJ11: =sum(AG11-AI11)/AI11 -> #DIV/0! | AL11: =AM11/$I$20 -> 0.067950247 | AM11: =AC11+AG11 -> 28072 | AN11: =SUM('2025'!B11:E11) -> 6714 | AO11: =sum(AM11-AN11)/AN11 -> 3.1811141 | AP11: =AQ11/$C$20 -> 0.0019850768 | AQ11: =TIKTOK!A112 -> 938 | AR11: 689 | AT11: =sum(AQ11-AS11)/AS11 -> #DIV/0! | AV11: =AW11/$I$20 -> 0.070220741 | AW11: =AM11+AQ11 -> 29010 | AX11: =SUM('2025'!B11:F11) -> 7043 | AY11: =sum(AW11-AX11)/AX11 -> 3.1189834
A12: World Plaza | B12: =C12/$C$20 -> 0.024389779 | C12: 11524.8 | D12: 11524.8 | F12: =sum(C12-E12)/E12 -> #DIV/0! | H12: =I12/$I$20 -> 0.027896587 | I12: =C12 -> 11524.8 | J12: 11524.8 | K12: =sum(I12-J12)/J12 -> 0 | L12: =M12/$C$20 -> 0.024389779 | M12: 11524.8 | N12: 11524.8 | P12: =sum(M12-O12)/O12 -> #DIV/0! | R12: =S12/$I$20 -> 0.055793175 | S12: =I12+M12 -> 23049.6 | T12: ='2025'!B12+'2025'!C12 -> 23049.6 | U12: =sum(S12-T12)/T12 -> 0 | V12: =W12/$C$20 -> 0.024389779 | W12: 11524.8 | X12: 11524.8 | Z12: =sum(W12-Y12)/Y12 -> #DIV/0! | AB12: =AC12/$I$20 -> 0.083689762 | AC12: =S12+W12 -> 34574.4 | AD12: =SUM('2025'!B12:D12) -> 34574.4 | AE12: =sum(AC12-AD12)/AD12 -> 0 | AF12: =AG12/$C$20 -> 0.024389779 | AG12: 11524.8 | AH12: 11524.8 | AJ12: =sum(AG12-AI12)/AI12 -> #DIV/0! | AL12: =AM12/$I$20 -> 0.11158635 | AM12: =AC12+AG12 -> 46099.2 | AN12: =SUM('2025'!B12:E12) -> 46099.2 | AO12: =sum(AM12-AN12)/AN12 -> 0 | AP12: =AQ12/$C$20 -> 0.024389779 | AQ12: 11524.8 | AR12: 11524.8 | AT12: =sum(AQ12-AS12)/AS12 -> #DIV/0! | AV12: =AW12/$I$20 -> 0.13948294 | AW12: =AM12+AQ12 -> 57624 | AX12: =SUM('2025'!B12:F12) -> 57624 | AY12: =sum(AW12-AX12)/AX12 -> 0
A13: The Finance | B13: =C13/$C$20 -> 0.07407003 | C13: 35000 | D13: 25000 | F13: =sum(C13-E13)/E13 -> #DIV/0! | H13: =I13/$I$20 -> 0.084719957 | I13: =C13 -> 35000 | J13: 25000 | K13: =sum(I13-J13)/J13 -> 0.4 | L13: =M13/$C$20 -> 0.07407003 | M13: 35000 | N13: 25000 | P13: =sum(M13-O13)/O13 -> #DIV/0! | R13: =S13/$I$20 -> 0.16943991 | S13: =I13+M13 -> 70000 | T13: ='2025'!B13+'2025'!C13 -> 52500 | U13: =sum(S13-T13)/T13 -> 0.33333333 | V13: =W13/$C$20 -> 0.07407003 | W13: 35000 | X13: 25000 | Z13: =sum(W13-Y13)/Y13 -> #DIV/0! | AB13: =AC13/$I$20 -> 0.25415987 | AC13: =S13+W13 -> 105000 | AD13: =SUM('2025'!B13:D13) -> 80000 | AE13: =sum(AC13-AD13)/AD13 -> 0.3125 | AF13: =AG13/$C$20 -> 0.07407003 | AG13: 35000 | AH13: 25000 | AJ13: =sum(AG13-AI13)/AI13 -> #DIV/0! | AL13: =AM13/$I$20 -> 0.33887983 | AM13: =AC13+AG13 -> 140000 | AN13: =SUM('2025'!B13:E13) -> 107500 | AO13: =sum(AM13-AN13)/AN13 -> 0.30232558 | AP13: =AQ13/$C$20 -> 0.07407003 | AQ13: 35000 | AR13: 25000 | AT13: =sum(AQ13-AS13)/AS13 -> #DIV/0! | AV13: =AW13/$I$20 -> 0.42359978 | AW13: =AM13+AQ13 -> 175000 | AX13: =SUM('2025'!B13:F13) -> 107500 | AY13: =sum(AW13-AX13)/AX13 -> 0.62790698
A14: Seibu | B14: =C14/$C$20 -> 0.025395439 | C14: 12000 | D14: 12000 | F14: =sum(C14-E14)/E14 -> #DIV/0! | H14: =I14/$I$20 -> 0.029046842 | I14: =C14 -> 12000 | J14: 12000 | K14: =sum(I14-J14)/J14 -> 0 | L14: =M14/$C$20 -> 0.025395439 | M14: 12000 | N14: 12000 | P14: =sum(M14-O14)/O14 -> #DIV/0! | R14: =S14/$I$20 -> 0.058093685 | S14: =I14+M14 -> 24000 | T14: ='2025'!B14+'2025'!C14 -> 24000 | U14: =sum(S14-T14)/T14 -> 0 | V14: =W14/$C$20 -> 0.025395439 | W14: 12000 | X14: 12000 | Z14: =sum(W14-Y14)/Y14 -> #DIV/0! | AB14: =AC14/$I$20 -> 0.087140527 | AC14: =S14+W14 -> 36000 | AD14: =SUM('2025'!B14:D14) -> 36000 | AE14: =sum(AC14-AD14)/AD14 -> 0 | AF14: =AG14/$C$20 -> 0.025395439 | AG14: 12000 | AH14: 12000 | AJ14: =sum(AG14-AI14)/AI14 -> #DIV/0! | AL14: =AM14/$I$20 -> 0.11618737 | AM14: =AC14+AG14 -> 48000 | AN14: =SUM('2025'!B14:E14) -> 48000 | AO14: =sum(AM14-AN14)/AN14 -> 0 | AP14: =AQ14/$C$20 -> 0.025395439 | AQ14: 12000 | AR14: 12000 | AT14: =sum(AQ14-AS14)/AS14 -> #DIV/0! | AV14: =AW14/$I$20 -> 0.14523421 | AW14: =AM14+AQ14 -> 60000 | AX14: =SUM('2025'!B14:F14) -> 60000 | AY14: =sum(AW14-AX14)/AX14 -> 0
A15: Grasshopper Concept | B15: =C15/$C$20 -> 0 | D15: 6000 | F15: =sum(C15-E15)/E15 -> #DIV/0! | H15: =I15/$I$20 -> 0 | I15: =C15 | J15: 6000 | K15: =sum(I15-J15)/J15 -> -1 | L15: =M15/$C$20 -> 0 | N15: 6000 | P15: =sum(M15-O15)/O15 -> #DIV/0! | R15: =S15/$I$20 -> 0 | S15: =I15+M15 -> 0 | T15: ='2025'!B15+'2025'!C15 -> 6000 | U15: =sum(S15-T15)/T15 -> -1 | V15: =W15/$C$20 -> 0 | X15: 6000 | Z15: =sum(W15-Y15)/Y15 -> #DIV/0! | AB15: =AC15/$I$20 -> 0 | AC15: =S15+W15 -> 0 | AD15: =SUM('2025'!B15:D15) -> 6000 | AE15: =sum(AC15-AD15)/AD15 -> -1 | AF15: =AG15/$C$20 -> 0 | AH15: 6000 | AJ15: =sum(AG15-AI15)/AI15 -> #DIV/0! | AL15: =AM15/$I$20 -> 0 | AM15: =AC15+AG15 -> 0 | AN15: =SUM('2025'!B15:E15) -> 6000 | AO15: =sum(AM15-AN15)/AN15 -> -1 | AP15: =AQ15/$C$20 -> 0 | AR15: 6000 | AT15: =sum(AQ15-AS15)/AS15 -> #DIV/0! | AV15: =AW15/$I$20 -> 0 | AW15: =AM15+AQ15 -> 0 | AX15: =SUM('2025'!B15:F15) -> 6000 | AY15: =sum(AW15-AX15)/AX15 -> -1
A16: Haleon | B16: =C16/$C$20 -> 0.023279152 | C16: 11000 | D16: 11000 | F16: =sum(C16-E16)/E16 -> #DIV/0! | H16: =I16/$I$20 -> 0.026626272 | I16: =C16 -> 11000 | K16: =sum(I16-J16)/J16 -> #DIV/0! | L16: =M16/$C$20 -> 0.023279152 | M16: 11000 | N16: 11000 | P16: =sum(M16-O16)/O16 -> #DIV/0! | R16: =S16/$I$20 -> 0.053252544 | S16: =I16+M16 -> 22000 | T16: ='2025'!B16+'2025'!C16 -> 0 | U16: =sum(S16-T16)/T16 -> #DIV/0! | V16: =W16/$C$20 -> 0.023279152 | W16: 11000 | X16: 11000 | Z16: =sum(W16-Y16)/Y16 -> #DIV/0! | AB16: =AC16/$I$20 -> 0.079878817 | AC16: =S16+W16 -> 33000 | AD16: =SUM('2025'!B16:D16) -> 0 | AE16: =sum(AC16-AD16)/AD16 -> #DIV/0! | AF16: =AG16/$C$20 -> 0.023279152 | AG16: 11000 | AH16: 11000 | AJ16: =sum(AG16-AI16)/AI16 -> #DIV/0! | AL16: =AM16/$I$20 -> 0.10650509 | AM16: =AC16+AG16 -> 44000 | AN16: =SUM('2025'!B16:E16) -> 0 | AO16: =sum(AM16-AN16)/AN16 -> #DIV/0! | AP16: =AQ16/$C$20 -> 0.023279152 | AQ16: 11000 | AR16: 11000 | AT16: =sum(AQ16-AS16)/AS16 -> #DIV/0! | AV16: =AW16/$I$20 -> 0.13313136 | AW16: =AM16+AQ16 -> 55000 | AX16: =SUM('2025'!B16:F16) -> 0 | AY16: =sum(AW16-AX16)/AX16 -> #DIV/0!
A17: AyalaLand - One Ayala | B17: =C17/$C$20 -> 0.10564079 | C17: 49918 | F17: =sum(C17-E17)/E17 -> #DIV/0! | H17: =I17/$I$20 -> 0.12083002 | I17: =C17 -> 49918 | L17: =M17/$C$20 -> 0.10564079 | M17: 49918 | P17: =sum(M17-O17)/O17 -> #DIV/0! | R17: =S17/$I$20 -> 0.24166005 | S17: =I17+M17 -> 99836 | T17: ='2025'!B17+'2025'!C17 -> 0 | V17: =W17/$C$20 -> 0.10564079 | W17: 49918 | Z17: =sum(W17-Y17)/Y17 -> #DIV/0! | AB17: =AC17/$I$20 -> 0.36249007 | AC17: =S17+W17 -> 149754 | AD17: =SUM('2025'!B17:D17) -> 0 | AF17: =AG17/$C$20 -> 0.10564079 | AG17: 49918 | AJ17: =sum(AG17-AI17)/AI17 -> #DIV/0! | AL17: =AM17/$I$20 -> 0.48332009 | AM17: =AC17+AG17 -> 199672 | AN17: =SUM('2025'!B17:E17) -> 0 | AP17: =AQ17/$C$20 -> 0.10564079 | AQ17: 49918 | AT17: =sum(AQ17-AS17)/AS17 -> #DIV/0! | AV17: =AW17/$I$20 -> 0.60415012 | AW17: =AM17+AQ17 -> 249590 | AX17: =SUM('2025'!B17:F17) -> 0
A18: AyalaLand - Greenbelt | B18: =C18/$C$20 -> 0.12570742 | C18: 59400 | F18: =sum(C18-E18)/E18 -> #DIV/0! | H18: =I18/$I$20 -> 0 | L18: =M18/$C$20 -> 0.12570742 | M18: 59400 | P18: =sum(M18-O18)/O18 -> #DIV/0! | R18: =S18/$I$20 -> 0.14378187 | S18: =I18+M18 -> 59400 | T18: ='2025'!B20+'2025'!C20 -> 780791.6 | V18: =W18/$C$20 -> 0.12570742 | W18: 59400 | Z18: =sum(W18-Y18)/Y18 -> #DIV/0! | AB18: =AC18/$I$20 -> 0.28756374 | AC18: =S18+W18 -> 118800 | AD18: =SUM('2025'!B18:D18) -> 0 | AF18: =AG18/$C$20 -> 0.12570742 | AG18: 59400 | AJ18: =sum(AG18-AI18)/AI18 -> #DIV/0! | AL18: =AM18/$I$20 -> 0.43134561 | AM18: =AC18+AG18 -> 178200 | AN18: =SUM('2025'!B18:E18) -> 0 | AP18: =AQ18/$C$20 -> 0 | AT18: =sum(AQ18-AS18)/AS18 -> #DIV/0! | AV18: =AW18/$I$20 -> 0.43134561 | AW18: =AM18+AQ18 -> 178200 | AX18: =SUM('2025'!B18:F18) -> 0
A19: Bazaar | B19: =C19/$C$20 -> 0 | F19: =sum(C19-E19)/E19 -> #DIV/0! | H19: =I19/$I$20 -> 0 | I19: =C19 | K19: =sum(I19-J19)/J19 -> #DIV/0! | L19: =M19/$C$20 -> 0 | P19: =sum(M19-O19)/O19 -> #DIV/0! | R19: =S19/$I$20 -> 0 | S19: =I19+M19 -> 0 | U19: =sum(S19-T19)/T19 -> #DIV/0! | V19: =W19/$C$20 -> 0 | Z19: =sum(W19-Y19)/Y19 -> #DIV/0! | AB19: =AC19/$I$20 -> 0 | AC19: =S19+W19 -> 0 | AE19: =sum(AC19-AD19)/AD19 -> #DIV/0! | AF19: =AG19/$C$20 -> 0 | AJ19: =sum(AG19-AI19)/AI19 -> #DIV/0! | AL19: =AM19/$I$20 -> 0 | AM19: =AC19+AG19 -> 0 | AN19: =SUM('2025'!B19:E19) -> 0 | AO19: =sum(AM19-AN19)/AN19 -> #DIV/0! | AP19: =AQ19/$C$20 -> 0 | AT19: =sum(AQ19-AS19)/AS19 -> #DIV/0! | AV19: =AW19/$I$20 -> 0 | AW19: =AM19+AQ19 -> 0 | AX19: =SUM('2025'!B19:F19) -> 0 | AY19: =sum(AW19-AX19)/AX19 -> #DIV/0!
A20: TOTAL WITH INDUSTRIAL | B20: =SUM(B2:B19) -> 1 | C20: =SUM(C2:C19) -> 472525.8 | D20: =SUM(D2:D19) -> 511044.8 | F20: =sum(C20-E20)/E20 -> #DIV/0! | G20: =SUM(G2:G19) -> 0 | H20: =SUM(H2:H19) -> 1 | I20: =SUM(I2:I19) -> 413125.8 | J20: =SUM(J2:J19) -> 454231.8 | K20: =sum(I20-J20)/J20 -> -0.090495646 | L20: =SUM(L2:L19) -> 0.9044285 | M20: =SUM(M2:M19) -> 427365.8 | N20: =SUM(N2:N19) -> 511044.8 | P20: =sum(M20-O20)/O20 -> #DIV/0! | Q20: =SUM(Q2:Q19) -> 0 | R20: =SUM(R2:R19) -> 2.0344689 | S20: =SUM(S2:S19) -> 840491.6 | T20: =SUM(T2:T19) -> 1561583.2 | U20: =sum(S20-T20)/T20 -> -0.46176957 | V20: =SUM(V2:V19) -> 0.86400108 | W20: =SUM(W2:W19) -> 408262.8 | X20: =SUM(X2:X19) -> 511044.8 | Z20: =sum(W20-Y20)/Y20 -> #DIV/0! | AA20: =SUM(AA2:AA19) -> 0 | AB20: =SUM(AB2:AB19) -> 3.0226977 | AC20: =SUM(AC2:AC19) -> 1248754.4 | AD20: =SUM(AD2:AD19) -> 1102868.4 | AE20: =sum(AC20-AD20)/AD20 -> 0.1322787 | AF20: =SUM(AF2:AF19) -> 0.89763522 | AG20: =SUM(AG2:AG19) -> 424155.8 | AH20: =SUM(AH2:AH19) -> 511044.8 | AJ20: =sum(AG20-AI20)/AI20 -> #DIV/0! | AK20: =SUM(AK2:AK19) -> 0 | AL20: =SUM(AL2:AL19) -> 4.0493966 | AM20: =SUM(AM2:AM19) -> 1672910.2 | AN20: =SUM(AN2:AN19) -> 1415272.2 | AO20: =sum(AM20-AN20)/AN20 -> 0.18204131 | AP20: =SUM(AP2:AP19) -> 0.42226012 | AQ20: =SUM(AQ2:AQ19) -> 199528.8 | AR20: =SUM(AR2:AR19) -> 511044.8 | AT20: =sum(AQ20-AS20)/AS20 -> #DIV/0! | AU20: =SUM(AU2:AU19) -> 0 | AV20: =SUM(AV2:AV19) -> 4.53237 | AW20: =SUM(AW2:AW19) -> 1872439 | AX20: =SUM(AX2:AX19) -> 1733750 | AY20: =sum(AW20-AX20)/AX20 -> 0.079993655
A22: INDUSTRIAL | C22: =sum(C12:C16) -> 69524.8 | F22: =sum(C22-E22)/E22 -> #DIV/0! | I22: =sum(I12:I16) -> 69524.8 | J22: =sum(J12:J16) -> 54524.8 | K22: =sum(I22-J22)/J22 -> 0.27510417 | M22: =sum(M12:M16) -> 69524.8 | P22: =sum(M22-O22)/O22 -> #DIV/0! | S22: =sum(S12:S16) -> 139049.6 | T22: =sum(T12:T16) -> 105549.6 | U22: =sum(S22-T22)/T22 -> 0.31738633 | W22: =sum(W12:W16) -> 69524.8 | Z22: =sum(W22-Y22)/Y22 -> #DIV/0! | AC22: =sum(AC12:AC16) -> 208574.4 | AD22: =sum(AD12:AD16) -> 156574.4 | AE22: =sum(AC22-AD22)/AD22 -> 0.33211049 | AG22: =sum(AG12:AG16) -> 69524.8 | AJ22: =sum(AG22-AI22)/AI22 -> #DIV/0! | AM22: =sum(AM12:AM16) -> 278099.2 | AN22: =sum(AN12:AN16) -> 207599.2 | AO22: =sum(AM22-AN22)/AN22 -> 0.33959668 | AQ22: =sum(AQ12:AQ16) -> 69524.8 | AT22: =sum(AQ22-AS22)/AS22 -> #DIV/0! | AW22: =sum(AW12:AW16) -> 347624 | AX22: =sum(AX12:AX16) -> 231124 | AY22: =sum(AW22-AX22)/AX22 -> 0.50405843
A23: RETAIL | C23: =sum(C2:C6) -> 209965 | D23: =sum(D2:D6) -> 237211 | I23: =sum(I2:I6) -> 209965 | J23: =sum(J2:J6) -> 278555 | M23: =sum(M2:M6) -> 162128 | N23: =sum(N2:N6) -> 237211 | S23: =sum(S2:S6) -> 372093 | T23: =sum(T2:T6) -> 433244 | W23: =sum(W2:W6) -> 138039 | X23: =sum(X2:X6) -> 237211 | AC23: =sum(AC2:AC6) -> 510132 | AD23: =sum(AD2:AD6) -> 610997 | AG23: =sum(AG2:AG6) -> 133130 | AH23: =sum(AH2:AH6) -> 237211 | AM23: =sum(AM2:AM6) -> 643262 | AN23: =sum(AN2:AN6) -> 753664 | AQ23: =sum(AQ2:AQ6) -> 0 | AR23: =sum(AR2:AR6) -> 237211 | AW23: =sum(AW2:AW6) -> 643262 | AX23: =sum(AX2:AX6) -> 946051
A24: ECOMMERCE | C24: =sum(C7:C11) -> 83718 | D24: =sum(D7:D11) -> 208309 | F24: =sum(C24-E24)/E24 -> #DIV/0! | G24: =sum(G7:G11) -> 0 | H24: =sum(H7:H11) -> 0.2026453 | I24: =sum(I7:I11) -> 83718 | J24: =sum(J7:J11) -> 121152 | K24: =sum(I24-J24)/J24 -> -0.30898376 | M24: =sum(M7:M11) -> 86395 | N24: =sum(N7:N11) -> 208309 | P24: =sum(M24-O24)/O24 -> #DIV/0! | Q24: =sum(Q7:Q11) -> 0 | R24: =sum(R7:R11) -> 0.41177046 | S24: =sum(S7:S11) -> 170113 | T24: =sum(T7:T11) -> 241998 | U24: =sum(S24-T24)/T24 -> -0.29704791 | W24: =sum(W7:W11) -> 91381 | X24: =sum(X7:X11) -> 208309 | Z24: =sum(W24-Y24)/Y24 -> #DIV/0! | AA24: =sum(AA7:AA11) -> 0 | AB24: =sum(AB7:AB11) -> 0.63296458 | AC24: =sum(AC7:AC11) -> 261494 | AD24: =sum(AD7:AD11) -> 335297 | AE24: =sum(AC24-AD24)/AD24 -> -0.22011232 | AG24: =sum(AG7:AG11) -> 112183 | AH24: =sum(AH7:AH11) -> 208309 | AJ24: =sum(AG24-AI24)/AI24 -> #DIV/0! | AK24: =sum(AK7:AK11) -> 0 | AL24: =sum(AL7:AL11) -> 0.90451141 | AM24: =sum(AM7:AM11) -> 373677 | AN24: =sum(AN7:AN11) -> 454009 | AO24: =sum(AM24-AN24)/AN24 -> -0.17693922 | AQ24: =sum(AQ7:AQ11) -> 80086 | AR24: =sum(AR7:AR11) -> 208309 | AT24: =sum(AQ24-AS24)/AS24 -> #DIV/0! | AU24: =sum(AU7:AU11) -> 0 | AV24: =sum(AV7:AV11) -> 1.0983652 | AW24: =sum(AW7:AW11) -> 453763 | AX24: =sum(AX7:AX11) -> 556575 | AY24: =sum(AW24-AX24)/AX24 -> -0.18472263
A25: TOTAL

Sheet ONLINE SUMMARY
C1: TOTAL SOLD OF STOCKS FOR LAZADA, SHOPEE , SHOPIFY, TIKTOK AND PICKAROO
C2: TOTAL IN VOLUME
A3: VARIANT | B3: PRICE | C3: JAN | D3: FEB | E3: MAR | F3: APR | G3: MAY | H3: JUN | I3: JUL | J3: AUG | K3: SEP | L3: OCT | M3: NOV | N3: DEC
A5: Quiet Elegance | B5: 329
A6: Charming Home | B6: 329
A7: Bright Mornings | B7: 329
A8: Relaxing Naturals | B8: 329 | C8: =LAZADA!U8+SHOPEE!CE8+SHOPIFY!F8+TIKTOK!G8+PICKAROO!N8 -> 16
A9: Mountain Breeze | B9: 329 | C9: =LAZADA!U9+SHOPEE!CE9+SHOPIFY!F9+TIKTOK!G9+PICKAROO!N9 -> 0
A10: Fresh Bamboo | B10: 329 | C10: =LAZADA!U10+SHOPEE!CE10+SHOPIFY!F10+TIKTOK!G10+PICKAROO!N10 -> 30
A11: Beach Escape | B11: 329 | C11: =LAZADA!U11+SHOPEE!CE11+SHOPIFY!F11+TIKTOK!G11+PICKAROO!N11 -> 5
A12: White Tea | B12: 329 | C12: =LAZADA!U12+SHOPEE!CE12+SHOPIFY!F12+TIKTOK!G12+PICKAROO!N12 -> 14
A13: Candy Cane | B13: 329 | C13: =LAZADA!U13+SHOPEE!CE13+SHOPIFY!F13+TIKTOK!G13+PICKAROO!N13 -> 3
A14: Apple Cinnamon | B14: 329 | C14: =LAZADA!U14+SHOPEE!CE14+SHOPIFY!F14+TIKTOK!G14+PICKAROO!N14 -> 9
A15: Easy Drive | B15: 219 | C15: =LAZADA!U15+SHOPEE!CE15+SHOPIFY!F15+TIKTOK!G15+PICKAROO!N15 -> 1
A16: InLove | C16: =LAZADA!U16+SHOPEE!CE16+SHOPIFY!F16+TIKTOK!G16+PICKAROO!N16 -> 0
A17: Bright Mornings HW | C17: =LAZADA!U17+SHOPEE!CE17+SHOPIFY!F17+TIKTOK!G17+PICKAROO!N17 -> 0
C18: =LAZADA!U18+SHOPEE!CE18+SHOPIFY!F18+TIKTOK!G18+PICKAROO!N18 -> 0
A19: Lavender | B19: 239 | C19: =LAZADA!U19+SHOPEE!CE19+SHOPIFY!F19+TIKTOK!G19+PICKAROO!N19 -> 2
A20: Eucalyptus | B20: 239 | C20: =LAZADA!U20+SHOPEE!CE20+SHOPIFY!F20+TIKTOK!G20+PICKAROO!N20 -> 3
A21: Peppermint | B21: 239 | C21: =LAZADA!U21+SHOPEE!CE21+SHOPIFY!F21+TIKTOK!G21+PICKAROO!N21 -> 1
A22: Fresh Bamboo FO | B22: 219 | C22: =LAZADA!U22+SHOPEE!CE22+SHOPIFY!F22+TIKTOK!G22+PICKAROO!N22 -> 3
A23: Beach Escape FO | B23: 219 | C23: =LAZADA!U23+SHOPEE!CE23+SHOPIFY!F23+TIKTOK!G23+PICKAROO!N23 -> 1
A24: White Tea FO | B24: 219 | C24: =LAZADA!U24+SHOPEE!CE24+SHOPIFY!F24+TIKTOK!G24+PICKAROO!N24 -> 0
A25: Bright Mornings FO | B25: 219 | C25: =LAZADA!U25+SHOPEE!CE25+SHOPIFY!F25+TIKTOK!G25+PICKAROO!N25 -> 0
A26: Quiet Elegance FO | B26: 219 | C26: =LAZADA!U26+SHOPEE!CE26+SHOPIFY!F26+TIKTOK!G26+PICKAROO!N26 -> 0
A27: Fresh Bamboo Diffuser | B27: 799 | C27: =LAZADA!U27+SHOPEE!CE27+SHOPIFY!F27+TIKTOK!G27+PICKAROO!N27 -> 2
A28: Clean Air | B28: 609 | C28: =LAZADA!U28+SHOPEE!CE28+SHOPIFY!F28+TIKTOK!G28+PICKAROO!N28 -> 6
A29: Cotton Clean | B29: 329 | C29: =LAZADA!U29+SHOPEE!CE29+SHOPIFY!F29+TIKTOK!G29+PICKAROO!N29 -> 24
A30: Brighter Days | B30: 329 | C30: =LAZADA!U30+SHOPEE!CE30+SHOPIFY!F30+TIKTOK!G30+PICKAROO!N30 -> 0
... A48: Simoy ng Pahiyas | B48: 0 | C48: =LAZADA!U48+SHOPEE!CE48+SHOPIFY!F48+TIKTOK!G48+PICKAROO!N48 -> 0
C49: =LAZADA!U49+SHOPEE!CE49+SHOPIFY!F49+TIKTOK!G49+PICKAROO!N49 -> 0
A50: Fresh Bamboo 500ml | B50: 609 | C50: =LAZADA!U50+SHOPEE!CE50+SHOPIFY!F50+TIKTOK!G50+PICKAROO!N50 -> 13
A51: White Tea 500ml | B51: 609 | C51: =LAZADA!U51+SHOPEE!CE51+SHOPIFY!F51+TIKTOK!G51+PICKAROO!N51 -> 3
A52: Tropical Paradise 200ml | B52: 329 | C52: =LAZADA!U52+SHOPEE!CE52+SHOPIFY!F52+TIKTOK!G52+PICKAROO!N52 -> 2
A53: RN Wash 100ml | B53: 199 | C53: =LAZADA!U53+SHOPEE!CE53+SHOPIFY!F53+TIKTOK!G53+PICKAROO!N53 -> 0
A54: CB Wash 100ml | B54: 199 | C54: =LAZADA!U54+SHOPEE!CE54+SHOPIFY!F54+TIKTOK!G54+PICKAROO!N54 -> 0
A55: Travel With Me | B55: 599 | C55: =LAZADA!U55+SHOPEE!CE55+SHOPIFY!F55+TIKTOK!G55+PICKAROO!N55 -> 0
A56: Handwash: Relaxing Naturals Gallon | B56: 1499 | C56: =LAZADA!U56+SHOPEE!CE56+SHOPIFY!F56+TIKTOK!G56+PICKAROO!N56 -> 0
C57: =LAZADA!U57+SHOPEE!CE57+SHOPIFY!F57+TIKTOK!G57+PICKAROO!N57 -> 0
A58: Creamy Matcha | B58: 329 | C58: =LAZADA!U58+SHOPEE!CE58+SHOPIFY!F58+TIKTOK!G58+PICKAROO!N58 -> 8
...

Sheet LAZADA
C2: JANUARY
A3: VARIANT | B3: PRICE | C3: Emily Pugat | D3: Christopher Mark . | E3: Claude Ponce | F3: Nelson Alfonso | G3: Barry Sia Lao Uy | H3: Sittie Aliyyah | I3: Patricia Jo Agarri | J3: Sadiri Eric Sanda. | K3: kenneth.grateco | L3: Jasmine C. villareal | M3: Valerie Ann Arana.. | N3: Myrcel Servano | O3: Christine B Ojeda | P3: Rei | Q3: Gary Galino | R3: Ashley Macabalo | S3: Alma | T3: Rodney Leo Santos | X3: Anna Margarita S | Y3: Hazel delos santos | Z3: Benjie Belotindos | AA3: Freeze Y | AB3: Sofia Galang | AC3: Jenny Lyn Castro | AD3: Julie Anne Garcia | AE3: Paula Madla Tuazon | AF3: Jessa Tabat Aranas | AG3: Grace Pascua | AH3: Marissa San Pedro | AI3: Jacqueline Batala. | AJ3: Melanie Montemayo. | AK3: Christopher Mark | AL3: Roj Tirona | AM3: Paula Madla Tuazon | AN3: Efren Cruz De Castro | AO3: Hermalyne Mediano | AP3: Third-Party-User | AQ3: Noel Joson | AR3: Sharon Garcia Cortez | AS3: China Golez | AT3: Aj Bobiles Naling | AU3: Shirley Petrasant.. | AV3: Rowena Alabado | AW3: Farzad Bahadoran | BA3: Trisha Yu | BB3: Josefino Mapor Co | BC3: Sara Jane Paderes | BD3: Ela Banaag | BE3: Rowleene | BF3: Rowena A. | BG3: Lei M. | BH3: Joji | BI3: TwoHun | BJ3: Sadiri Eric Sanda | BK3: Cynthia Ducalang BD | BL3: Tristram David | BM3: Sadiri Eric Sanda. | BN3: Mary Grace R. | BO3: Jen | BP3: Karen Faye Bathan | BQ3: Christopher | BR3: 917 | BS3: JessaA | BT3: 947 | BU3: Rainer | BV3: Rowlene | BW3: James Holand | BX3: Marlyn | BY3: Mary Grace | CD3: Sheen Patrick S | CE3: Jelen Perlas P | CF3: Marlyn Lao | CG3: Ronald Nepomuceno. | CH3: Mariel Zamora | CI3: Sidney Alan Tagle | CJ3: Derick John Mestio | CK3: Orlando III Cabud | CL3: Dhivya R | CM3: Napoleon banzuela | CN3: Ninty four | CO3: Rowena Alabado | CP3: Danny Santillan | CQ3: Rizalyn Rodriguez | CR3: MF Jawid | CS3: MERLA LAINE FLORE | CT3: Emily Mediodia P | CU3: One Two | CV3: Honelet Cumabig | CW3: Anabel Manuel | CX3: carolyn calanoy | CY3: Nine | CZ3: Maria Crizelda C | DA3: Sheila Constantin. | DB3: Lean Ramirez Angel | DC3: Luisa Rivero | DD3: Prosperity | DE3: Marissa San Pedro | DF3: Ethelene Gamboa | DG3: melody clark | DH3: Leonard Sy Gaw | DL3: Jeanefer RUIZ | DM3: Maria Joy Camacho | DN3: Ruel Linas Dael | DO3: Jaime Olbes | DP3: Nelson Baloloy Og | DQ3: jim contes | DR3: Noel reginald Tam | DS3: Marie Belen Erfe | DT3: Ma Christina Jaci. | DU3: Sixseven | DV3: Stephen Liam Ybud. | DW3: Ma Luisa | DX3: Monchito | DY3: Sixseven | DZ3: Ronel Erpe Eva | EA3: Nory | EB3: Paula Eunice | EC3: Noel reginald T | ED3: Lyn Yumang | EE3: Jonas Polines | EF3: Carmela A. | EG3: Elaine Torrejo | EH3: Sixty | EI3: Tristan Jerome Pa.. | EJ3: Hamid | EK3: Maria Camille Amba | EL3: Love | EM3: Seven8 | EN3: Ken My | EO3: Christine Buenvia | EP3: Sheen Patrick Sor | EQ3: Twohun
C4: 45658 | D4: 45661 | E4: 45662 | F4: 45662 | G4: 45662 | H4: 45663 | I4: 45666 | J4: 45670 | K4: 45670 | L4: 45671 | M4: 45672 | N4: 45676 | O4: 45677 | P4: 45683 | Q4: 45685 | R4: 45687 | S4: 45687 | T4: 45687 | X4: 45689 | Y4: 45690 | Z4: 45691 | AA4: 45691 | AB4: 45691 | AC4: 45691 | AD4: 45692 | AE4: 45693 | AF4: 45694 | AG4: 45695 | AH4: 45696 | AI4: 45696 | AJ4: 45696 | AK4: 45697 | AL4: 45698 | AM4: 45706 | AN4: 45707 | AO4: 45708 | AP4: 45709 | AQ4: 45710 | AR4: 45710 | AS4: 45710 | AT4: 45713 | AU4: 45713 | AV4: 45714 | AW4: 45715 | BA4: 45717 | BB4: 45718 | BC4: 45719 | BD4: 45719 | BE4: 45720 | BF4: 45724 | BG4: 45722 | BH4: 45723 | BI4: 45728 | BJ4: 45730 | BK4: 45731 | BL4: 45732 | BM4: 45733 | BN4: 45734 | BO4: 45736 | BP4: 45737 | BQ4: 45738 | BR4: 45739 | BS4: 45740 | BT4: 45741 | BU4: 45742 | BV4: 45743 | BW4: 45744 | BX4: 45745 | BY4: 45746 | CD4: 45749 | CE4: 45750 | CF4: 45751 | CG4: 45751 | CH4: 45752 | CI4: 45754 | CJ4: 45754 | CK4: 45757 | CL4: 45757 | CM4: 45757 | CN4: 45758 | CO4: 45758 | CP4: 45758 | CQ4: 45759 | CR4: 45759 | CS4: 45760 | CT4: 45760 | CU4: 45761 | CV4: 45762 | CW4: 45763 | CX4: 45767 | CY4: 45769 | CZ4: 45770 | DA4: 45772 | DB4: 45773 | DC4: 45773 | DD4: 45774 | DE4: 45775 | DF4: 45776 | DG4: 45776 | DH4: 45777 | DL4: 45778 | DM4: 45779 | DN4: 45780 | DO4: 45781 | DP4: 45782 | DQ4: 45783 | DR4: 45784 | DS4: 45785 | DT4: 45785 | DU4: 45786 | DV4: 45787 | DW4: 45788 | DX4: 45788 | DY4: 45791 | DZ4: 45793 | EA4: 45793 | EB4: 45793 | EC4: 45793 | ED4: 45794 | EE4: 45794 | EF4: 45795 | EG4: 45795 | EH4: 45796 | EI4: 45796 | EJ4: 45796 | EK4: 45796 | EL4: 45796 | EM4: 45797 | EN4: 45798 | EO4: 45799 | EP4: 45799 | EQ4: 45800
A5: Quiet Elegance | B5: 329
A6: Charming Home | B6: 329
A7: Bright Mornings | B7: 329
A8: Relaxing Naturals | B8: 329 | E8: 1 | N8: 2 | U8: =sum(C8:T8) -> 3 | V8: =U8*B8 -> 987 | AB8: 1 | AJ8: 1 | AX8: =sum(X8:AW8) -> 2 | AY8: =AX8*B8 -> 658 | BE8: 1 | BV8: 1 | BX8: 2 | CA8: =sum(BA8:BY8) -> 4 | CB8: =B8*CA8 -> 1316 | EG8: 1
A9: Mountain Breeze | B9: 329 | U9: =sum(C9:T9) -> 0 | V9: =U9*B9 -> 0 | AX9: =sum(X9:AW9) -> 0 | AY9: =AX9*B9 -> 0 | CA9: =sum(BA9:BE9) -> 0 | CB9: =CA9*AT9 -> 0
A10: Fresh Bamboo | B10: 329 | M10: 1 | N10: 3 | P10: 3 | U10: =sum(C10:T10) -> 7 | V10: =U10*B10 -> 2303 | AJ10: 1 | AO10: 1 | AU10: 1 | AX10: =sum(X10:AW10) -> 3 | AY10: =AX10*B10 -> 987 | CA10: =sum(BA10:BY10) -> 0 | CB10: =B10*CA10 -> 0
A11: Beach Escape | B11: 329 | N11: 2 | U11: =sum(C11:T11) -> 2 | V11: =U11*B11 -> 658 | AX11: =sum(X11:AW11) -> 0 | AY11: =AX11*B11 -> 0 | BB11: 1 | CA11: =sum(BA11:BY11) -> 1 | CB11: =B11*CA11 -> 329 | CL11: 1 | CY11: 1 | DS11: 1
A12: White Tea | B12: 329 | N12: 2 | U12: =sum(C12:T12) -> 2 | V12: =U12*B12 -> 658 | AN12: 1 | AX12: =sum(X12:AW12) -> 1 | AY12: =AX12*B12 -> 329 | BA12: 1 | BC12: 1 | BP12: 1 | CA12: =sum(BA12:BY12) -> 3 | CB12: =B12*CA12 -> 987 | CV12: 1 | DL12: 1 | DU12: 1 | EB12: 1
A13: Candy Cane | B13: 329 | U13: =sum(C13:T13) -> 0 | V13: =U13*B13 -> 0 | AQ13: 3 | AX13: =sum(X13:AW13) -> 3 | AY13: =AX13*B13 -> 987 | BS13: 1 | CA13: =sum(BA13:BY13) -> 1 | CB13: =B13*CA13 -> 329 | DL13: 1 | DW13: 1
A14: Apple Cinnamon | B14: 329 | Q14: 1 | U14: =sum(C14:T14) -> 1 | V14: =U14*B14 -> 329 | AP14: 1 | AX14: =sum(X14:AW14) -> 1 | AY14: =AX14*B14 -> 329 | BI14: 1 | BO14: 1 | BS14: 1 | BT14: 1 | CA14: =sum(BA14:BY14) -> 4 | CB14: =B14*CA14 -> 1316 | CN14: 2 | CV14: 1 | DR14: 1 | DW14: 1 | EC14: 2 | ED14: 1 | EE14: 1 | EL14: 2 | EQ14: 2
A15: Easy Drive | B15: 219 | U15: =sum(C15:T15) -> 0 | V15: =U15*B15 -> 0 | AD15: 1 | AX15: =sum(X15:AW15) -> 1 | AY15: =AX15*B15 -> 219 | CA15: =sum(BA15:BY15) -> 0 | CB15: =B15*CA15 -> 0
A16: InLove | U16: =sum(C16:T16) -> 0 | V16: =U16*B16 -> 0 | AX16: =sum(X16:AW16) -> 0 | AY16: =AX16*B16 -> 0 | CA16: =sum(BA16:BY16) -> 0 | CB16: =B16*CA16 -> 0
A17: Bright Mornings HW | U17: =sum(C17:T17) -> 0 | V17: =U17*B17 -> 0 | AX17: =sum(X17:AW17) -> 0 | AY17: =AX17*B17 -> 0 | CA17: =sum(BA17:BY17) -> 0 | CB17: =B17*CA17 -> 0
U18: =sum(C18:T18) -> 0 | V18: =U18*B18 -> 0 | AX18: =sum(X18:AW18) -> 0 | AY18: =AX18*B18 -> 0 | CA18: =sum(BA18:BY18) -> 0 | CB18: =B18*CA18 -> 0
A19: Lavender | B19: 239 | U19: =sum(C19:T19) -> 0 | V19: =U19*B19 -> 0 | AR19: 1 | AX19: =sum(X19:AW19) -> 1 | AY19: =AX19*B19 -> 239 | CA19: =sum(BA19:BY19) -> 0 | CB19: =B19*CA19 -> 0
A20: Eucalyptus | B20: 239 | C20: 1 | E20: 1 | U20: =sum(C20:T20) -> 2 | V20: =U20*B20 -> 478 | AX20: =sum(X20:AW20) -> 0 | AY20: =AX20*B20 -> 0 | CA20: =sum(BA20:BY20) -> 0 | CB20: =B20*CA20 -> 0
A21: Peppermint | B21: 239 | U21: =sum(C21:T21) -> 0 | V21: =U21*B21 -> 0 | AX21: =sum(X21:AW21) -> 0 | AY21: =AX21*B21 -> 0 | CA21: =sum(BA21:BY21) -> 0 | CB21: =B21*CA21 -> 0 | CD21: 2 | EP21: 1
A22: Fresh Bamboo FO | B22: 219 | U22: =sum(C22:T22) -> 0 | V22: =U22*B22 -> 0 | AX22: =sum(X22:AW22) -> 0 | AY22: =AX22*B22 -> 0 | BH22: 1 | CA22: =sum(BA22:BY22) -> 1 | CB22: =B22*CA22 -> 219
A23: Beach Escape FO | B23: 219 | U23: =sum(C23:T23) -> 0 | V23: =U23*B23 -> 0 | AX23: =sum(X23:AW23) -> 0 | AY23: =AX23*B23 -> 0 | CA23: =sum(BA23:BY23) -> 0 | CB23: =B23*CA23 -> 0
A24: White Tea FO | B24: 219 | U24: =sum(C24:T24) -> 0 | V24: =U24*B24 -> 0 | AX24: =sum(X24:AW24) -> 0 | AY24: =AX24*B24 -> 0 | CA24: =sum(BA24:BY24) -> 0 | CB24: =B24*CA24 -> 0
A25: Bright Mornings FO | B25: 219 | U25: =sum(C25:T25) -> 0 | V25: =U25*B25 -> 0 | AX25: =sum(X25:AW25) -> 0 | AY25: =AX25*B25 -> 0 | CA25: =sum(BA25:BY25) -> 0 | CB25: =B25*CA25 -> 0
A26: Quiet Elegance FO | B26: 219 | U26: =sum(C26:T26) -> 0 | V26: =U26*B26 -> 0 | AX26: =sum(X26:AW26) -> 0 | AY26: =AX26*B26 -> 0 | CA26: =sum(BA26:BY26) -> 0 | CB26: =B26*CA26 -> 0
A27: Fresh Bamboo Diffuser | B27: 799 | U27: =sum(C27:T27) -> 0 | V27: =U27*B27 -> 0 | Y27: 1 | AX27: =sum(X27:AW27) -> 1 | AY27: =AX27*B27 -> 799 | CA27: =sum(BA27:BY27) -> 0 | CB27: =B27*CA27 -> 0
A28: Clean Air | B28: 609 | K28: 1 | N28: 1 | U28: =sum(C28:T28) -> 2 | V28: =U28*B28 -> 1218 | Z28: 1 | AI28: 3 | AX28: =sum(X28:AW28) -> 4 | AY28: =AX28*B28 -> 2436 | CA28: =sum(BA28:BY28) -> 0 | CB28: =B28*CA28 -> 0
A29: Cotton Clean | B29: 329 | G29: 1 | K29: 1 | N29: 3 | Q29: 1 | T29: 1 | U29: =sum(C29:T29) -> 7 | V29: =U29*B29 -> 2303 | AH29: 1 | AS29: 1 | AU29: 3 | AX29: =sum(X29:AW29) -> 5 | AY29: =AX29*B29 -> 1645 | BN29: 2 | CA29: =sum(BA29:BY29) -> 2 | CB29: =B29*CA29 -> 658 | DS29: 1 | DT29: 1 | ED29: 1
A30: Brighter Days | B30: 329 | U30: =sum(C30:T30) -> 0 | V30: =U30*B30 -> 0 | AX30: =sum(X30:AW30) -> 0 | AY30: =AX30*B30 -> 0 | CA30: =sum(BA30:BY30) -> 0 | CB30: =B30*CA30 -> 0
A31: Cotton Clean FO | B31: 219 | U31: =sum(C31:T31) -> 0 | V31: =U31*B31 -> 0 | AX31: =sum(X31:AW31) -> 0 | AY31: =AX31*B31 -> 0 | CA31: =sum(BA31:BY31) -> 0 | CB31: =B31*CA31 -> 0 | EF31: 1
A32: Brighter Days EO | B32: 219 | U32: =sum(C32:T32) -> 0 | V32: =U32*B32 -> 0 | AX32: =sum(X32:AW32) -> 0 | AY32: =AX32*B32 -> 0 | CA32: =sum(BA32:BY32) -> 0 | CB32: =B32*CA32 -> 0
A33: Fresh Bamboo Refill | B33: 439 | O33: 2 | U33: =sum(C33:T33) -> 2 | V33: =U33*B33 -> 878 | AX33: =sum(X33:AW33) -> 0 | AY33: =AX33*B33 -> 0 | CA33: =sum(BA33:BY33) -> 0 | CB33: =B33*CA33 -> 0 | DB33: 1
A34: Clean Air Refill 1000ml | B34: 899 | U34: =sum(C34:T34) -> 0 | V34: =U34*B34 -> 0 | AX34: =sum(X34:AW34) -> 0 | AY34: =AX34*B34 -> 0 | CA34: =sum(BA34:BY34) -> 0 | CB34: =B34*CA34 -> 0
A35: Waterbased: Fresh Bamboo | B35: 549 | R35: 1 | U35: =sum(C35:T35) -> 1 | V35: =U35*B35 -> 549 | AV35: 1 | AX35: =sum(X35:AW35) -> 1 | AY35: =AX35*B35 -> 549 | BF35: 1 | CA35: =sum(BA35:BY35) -> 1 | CB35: =B35*CA35 -> 549 | CO35: 2 | EI35: 1 | EK35: 1
A36: Waterbased: Cotton Clean | B36: 549 | U36: =sum(C36:T36) -> 0 | V36: =U36*B36 -> 0 | AV36: 2 | AX36: =sum(X36:AW36) -> 2 | AY36: =AX36*B36 -> 1098 | BF36: 1 | CA36: =sum(BA36:BY36) -> 1 | CB36: =B36*CA36 -> 549 | CO36: 2
A37: Waterbased: White Tea | B37: 549 | U37: =sum(C37:T37) -> 0 | V37: =U37*B37 -> 0 | AT37: 2 | AX37: =sum(X37:AW37) -> 2 | AY37: =AX37*B37 -> 1098 | CA37: =sum(BA37:BY37) -> 0 | CB37: =B37*CA37 -> 0 | CO37: 2 | EI37: 1
A38: White Tea Diffuser | B38: 799 | U38: =sum(C38:T38) -> 0 | V38: =U38*B38 -> 0 | AX38: =sum(X38:AW38) -> 0 | AY38: =AX38*B38 -> 0 | CA38: =sum(BA38:BY38) -> 0 | CB38: =B38*CA38 -> 0 | EN38: 1
A39: Cotton Clean Diffuser | B39: 799 | U39: =sum(C39:T39) -> 0 | V39: =U39*B39 -> 0 | AX39: =sum(X39:AW39) -> 0 | AY39: =AX39*B39 -> 0 | CA39: =sum(BA39:BY39) -> 0 | CB39: =B39*CA39 -> 0
A40: White Tea Diffuser Refill | B40: 439 | U40: =sum(C40:T40) -> 0 | V40: =U40*B40 -> 0 | AX40: =sum(X40:AW40) -> 0 | AY40: =AX40*B40 -> 0 | CA40: =sum(BA40:BY40) -> 0 | CB40: =B40*CA40 -> 0 | DB40: 1 | EJ40: 1
A41: Cotton Clean Diffuser Refill | B41: 439 | U41: =sum(C41:T41) -> 0 | V41: =U41*B41 -> 0 | AX41: =sum(X41:AW41) -> 0 | AY41: =AX41*B41 -> 0 | CA41: =sum(BA41:BY41) -> 0 | CB41: =B41*CA41 -> 0 | CP41: 1
...

Sheet SHOPEE
CH2: FEBRUARY
A3: VARIANT | B3: PRICE | C3: Veron Migo-Engle | D3: Cristine | E3: Jdavecve | F3: Maureen | G3: Cat Tan | H3: Marie Rose | I3: necitascruz | J3: Romeo | K3: Dawn Silva | L3: Haydee Chan | M3: Erica M. | N3: Joanna | O3: Ella | P3: Gerliz | Q3: Berlyn | R3: Java M. | S3: Diosa D. | T3: Black S. | U3: Ruth M. | V3: Jarssry | W3: Total | X3: Ires | Y3: Rein Magno | Z3: Alex | AA3: Marie J. | AB3: Dyu An | AC3: Jhanel | AD3: Eugene E. Guibao | AE3: Peng p. | AF3: Myra Brockmann | AG3: Pobadora | AH3: Hiro | AI3: Judy | AJ3: Borex | AK3: Cever | AL3: Ferdinand | AM3: Matthew | AN3: Carol | AO3: Green Apple | AP3: Henry Villadares | AQ3: Via bells | AR3: Carol V. | AS3: Che galang | AT3: Dr. Tine | AU3: Page 26 | AV3: Dhan | AW3: Edlyn Mancera | AX3: Sofia | AY3: Veron | AZ3: Rhea V. | BA3: Claudine Manuel | BB3: Ivygail Javier | BC3: Bubbles F. | BD3: Kasumi Inoue | BE3: Jessa Lique | BF3: Karen S. | BG3: Summer Ebo | BH3: Pauline Ann Pablo | BI3: Keyt Q. | BJ3: Jenny D. | BK3: Ron Galde | BL3: Cedric C. | BM3: Junjun L. | BN3: Joseph Mamac | BO3: Sammon | BP3: Threex | BQ3: Paul Dequina | BR3: Maia | BS3: Kingraw | BT3: La Taperia Martinez | BU3: Dani Feliza Caparas | BV3: Celin Gay Balgos | BW3: Ani Freak | BX3: Carrys | BY3: Elle J. | BZ3: Thresex | CA3: Lea Nicole Bagayas | CB3: Gigi | CC3: Faith | CD3: Solution Trading | CH3: Jestoni L. | CI3: Dencice J. | CJ3: Hana | CK3: Jen Irin | CL3: Elle J. | CM3: Leo Rosario | CN3: Belle Santos | CO3: Jestoni Losabia | CP3: Shenna | CQ3: Claire D. | CR3: Pretty D. | CS3: Maksi mutin | CT3: Hilda Rivadelo | CU3: Katlyn | CV3: Jenny Dayon | CW3: Gaby Pama | CX3: Roxanne Dalistan | CY3: Edmaria | CZ3: Ellaine Lois Megia | DA3: Eleonor | DB3: Miles C. | DC3: Aurdey | DD3: Josephine Candaroma | DE3: Edlyn M. | DF3: Hazel C. | DG3: Dani F. | DH3: Flade J. | DI3: Wear H. | DJ3: Gabrielle | DK3: Nikki J. | DL3: VHB Paseo Skin Care Center Inc | DM3: Jef Tumampos | DN3: Cruzer | DO3: Michelle Tan | DP3: Krl franco | DQ3: Jeanne Pauline M Baligod | DR3: Michelle Tan | DS3: Dianna | DT3: Salem | DU3: Barbie Castaneda | DV3: Jenny Dayon | DW3: Leo M. | DX3: Michelle Tan | DY3: Michelle Tan | DZ3: Angela Mae Gilboy | EA3: Janika Laxamana | EB3: Pauline Ann Pablo | EC3: Maria Teresa A. Pacil | ED3: Vanessa Chanyungco | EE3: Carol Villena | EI3: Solution Trading | EJ3: Sandra | EK3: Maek M. | EL3: Anna F. | EM3: Bhie M. | EN3: Lisha | EO3: Jack | EP3: Nessa | EQ3: Thirsty | ER3: Carlie | ES3: Thirsty | ET3: Carlie | EU3: MelBad | EV3: Cervin Benjamin Sarte | EW3: Lee Santos | EX3: Hernan | EY3: Danifel | EZ3: Esbaro | FA3: Theen | FB3: Mylds Corner | FC3: Zarren Lee | FD3: Jhanel | FE3: Niki Mindj | FF3: Mae Joson | FG3: Giigii | FH3: Mary Antoinette Maneja | FI3: Tricia | FJ3: Lorie | FK3: Cindy | FL3: Bonifcio | FM3: Melanie Pilapil | FN3: Raenna | FO3: Leo Rosario | FP3: Pegy | FQ3: Rowena | FR3: Mribeth | FS3: Ness | FT3: Pink | FU3: small | FV3: next level | FW3: Black | FX3: Anne B. | FY3: SD T. | FZ3: Vayie | GA3: Irres | GB3: Gmm | GC3: Mae Nova | GD3: JF24 | GE3: JF24 | GF3: Marian Marites | GG3: Antonette Amancio | GK3: Althea Napod | GL3: Rhea M. | GM3: Carol | GN3: Cpb | GO3: Juliene | GP3: Sleep Les | GQ3: Jennifer | GR3: Lea L. | GS3: Genelyn | GT3: Sugar Plum | GU3: Judith Nicolas | GV3: Julia K. | GW3: Paulo King | GX3: Jess Theway | GY3: Alexa | GZ3: Eowyn | HA3: Robert Cruz | HB3: Pauline Ann Pablo | HC3: Ma. Majella Fides Conti | HD3: Q3pvytn | HE3: Camille | HF3: Dani Feliza Caparas | HG3: Amanda F. | HH3: Sophia | HI3: Fe de Guzman | HJ3: Eunice | HK3: Edlyn Mancera | HL3: Blesilda Dy | HM3: Mickayoo | HN3: Jessica Tan | HO3: Leo Rosario | HP3: Leo Rosario | HQ3: Peace | HR3: One belle | HS3: Yvonne Casabuena | HT3: Takahiro | HU3: Prime | HV3: Armie | HW3: Xyza Ledesma | HX3: Ann Melody Yao | HY3: Maja | HZ3: Battos | IA3: Rhea M | IB3: Budweizen | IC3: Samun | ID3: Mirman | IE3: Michael | II3: Dani F. | IJ3: Catetan | IK3: Kathlyn chaves | IL3: Shane Bacoy | IM3: Ma. Lucilyn Fajanilan | IN3: Merlin | IO3: Anjeline | IP3: Sherlan | IQ3: Martin | IR3: Jinse | IS3: Pablo | IT3: Thebab | IU3: Denice | IV3: Triss | IW3: Sighter | IX3: Siyvie | IY3: King | IZ3: Brie | JA3: Mg Narcisso | JB3: Jenefer ancheta | JC3: Wilma | JD3: Chris Ramos | JE3: Demensyon | JF3: Qep | JG3: Teejay | JH3: Julie | JI3: Bernadette Cadaing | JJ3: Sanmi | JK3: Edmarie | JL3: Beautie | JM3: Patisha | JN3: Sighter | JO3: Euna | JP3: Hazel | JQ3: Jona Francisco | JR3: Pau ramos | JS3: Lisette | JT3: Jacky Guillen | JU3: Mike | JV3: Eloise | JW3: JTakahiro | JX3: Feliz | JY3: Denice Javier | JZ3: Jeremie Tumulak | KA3: Bena Malabanan
C4: 45658 | D4: 45659 | E4: 45659 | F4: 45660 | G4: 45660 | H4: 45661 | I4: 45661 | J4: 45662 | K4: 45663 | L4: 45663 | M4: 45663 | N4: 45663 | O4: 45663 | P4: 45664 | Q4: 45664 | R4: 45664 | S4: 45664 | T4: 45665 | U4: 45666 | V4: 45666 | W4: 45667 | X4: 45667 | Y4: 45668 | Z4: 45668 | AA4: 45668 | AB4: 45669 | AC4: 45670 | AD4: 45671 | AE4: 45672 | AF4: 45672 | AG4: 45672 | AH4: 45672 | AI4: 45672 | AJ4: 45672 | AK4: 45672 | AL4: 45673 | AM4: 45673 | AN4: 45674 | AO4: 45675 | AP4: 45676 | AQ4: 45677 | AR4: 45678 | AS4: 45678 | AT4: 45679 | AU4: 45679 | AV4: 45679 | AW4: 45680 | AX4: 45680 | AY4: 45681 | AZ4: 45681 | BA4: 45681 | BB4: 45681 | BC4: 45681 | BD4: 45682 | BE4: 45683 | BF4: 45683 | BG4: 45683 | BH4: 45684 | BI4: 45684 | BJ4: 45684 | BK4: 45684 | BL4: 45684 | BM4: 45684 | BN4: 45684 | BO4: 45685 | BP4: 45685 | BQ4: 45685 | BR4: 45685 | BS4: 45685 | BT4: 45686 | BU4: 45686 | BV4: 45687 | BW4: 45687 | BX4: 45687 | BY4: 45687 | BZ4: 45688 | CA4: 45688 | CB4: 45688 | CC4: 45688 | CD4: 45688 | CH4: 45689 | CI4: 45689 | CJ4: 45690 | CK4: 45690 | CL4: 45690 | CM4: 45690 | CN4: 45690 | CO4: 45692 | CP4: 45692 | CQ4: 45693 | CR4: 45693 | CS4: 45695 | CT4: 45695 | CU4: 45695 | CV4: 45696 | CW4: 45697 | CX4: 45698 | CY4: 45698 | CZ4: 45699 | DA4: 45700 | DB4: 45701 | DC4: 45702 | DD4: 45703 | DE4: 45703 | DF4: 45703 | DG4: 45703 | DH4: 45703 | DI4: 45703 | DJ4: 45704 | DK4: 45705 | DL4: 45705 | DM4: 45706 | DN4: 45707 | DO4: 45707 | DP4: 45708 | DQ4: 45709 | DR4: 45709 | DS4: 45710 | DT4: 45711 | DU4: 45711 | DV4: 45711 | DW4: 45711 | DX4: 45712 | DY4: 45713 | DZ4: 45713 | EA4: 45713 | EB4: 45713 | EC4: 45714 | ED4: 45715 | EE4: 45716 | EI4: 46082 | EJ4: 46082 | EK4: 46082 | EL4: 46082 | EM4: 46083 | EN4: 46085 | EO4: 46086 | EP4: 46086 | EQ4: 46087 | ER4: 46087 | ES4: 46087 | ET4: 46087 | EU4: 46089 | EV4: 46090 | EW4: 46090 | EX4: 46092 | EY4: 46093 | EZ4: 46094 | FA4: 46094 | FB4: 46095 | FC4: 46096 | FD4: 46096 | FE4: 46096 | FF4: 46096 | FG4: 46097 | FH4: 46097 | FI4: 46097 | FJ4: 46098 | FK4: 46099 | FL4: 46099 | FM4: 46100 | FN4: 46101 | FO4: 46101 | FP4: 46102 | FQ4: 46103 | FR4: 46104 | FS4: 46105 | FT4: 46106 | FU4: 46107 | FV4: 46107 | FW4: 46107 | FX4: 46108 | FY4: 46109 | FZ4: 46111 | GA4: 46111 | GB4: 46111 | GC4: 46111 | GD4: 46112 | GE4: 46112 | GF4: 46112 | GG4: 46112 | GK4: 45748 | GL4: 45748 | GM4: 45751 | GN4: 45751 | GO4: 45751 | GP4: 45751 | GQ4: 45751 | GR4: 45752 | GS4: 45752 | GT4: 45753 | GU4: 45753 | GV4: 45754 | GW4: 45756 | GX4: 45756 | GY4: 45758 | GZ4: 45758 | HA4: 45758 | HB4: 45759 | HC4: 45759 | HD4: 45759 | HE4: 45760 | HF4: 45760 | HG4: 45761 | HH4: 45762 | HI4: 45762 | HJ4: 45763 | HK4: 45763 | HL4: 45764 | HM4: 45764 | HN4: 45766 | HO4: 45768 | HP4: 45768 | HQ4: 45768 | HR4: 45769 | HS4: 45769 | HT4: 45770 | HU4: 45770 | HV4: 45771 | HW4: 45772 | HX4: 45772 | HY4: 45773 | HZ4: 45774 | IA4: 45774 | IB4: 45775 | IC4: 45776 | ID4: 45777 | IE4: 45777 | II4: 45778 | IJ4: 45780 | IK4: 45780 | IL4: 45782 | IM4: 45782 | IN4: 45782 | IO4: 45782 | IP4: 45782 | IQ4: 45783 | IR4: 45783 | IS4: 45783 | IT4: 45784 | IU4: 45784 | IV4: 45785 | IW4: 45786 | IX4: 45786 | IY4: 45786 | IZ4: 45787 | JA4: 45789 | JB4: 45789 | JC4: 45789 | JD4: 45790 | JE4: 45790 | JF4: 45790 | JG4: 45792 | JH4: 45792 | JI4: 45793 | JJ4: 45793 | JK4: 45794 | JL4: 45794 | JM4: 45794 | JN4: 45794 | JO4: 45794 | JP4: 45794 | JQ4: 45795 | JR4: 45796 | JS4: 45798 | JT4: 45798 | JU4: 45799 | JV4: 45799 | JW4: 45799 | JX4: 45800 | JY4: 45801 | JZ4: 45801 | KA4: 45802
A5: Quiet Elegance | B5: 329
A6: Charming Home | B6: 329
A7: Bright Mornings | B7: 329
A8: Relaxing Naturals | B8: 329 | C8: 1 | F8: 1 | AB8: 1 | AH8: 1 | AP8: 2 | AQ8: 1 | AX8: 1 | AY8: 1 | BG8: 1 | BL8: 1 | BN8: 1 | BU8: 1 | CE8: =sum(C8:CD8) -> 13 | CF8: =CE8*B8 -> 4277 | DF8: 1 | DG8: 1 | DH8: 1 | DK8: 1 | DN8: 1 | DT8: 1 | DZ8: 1 | EA8: 1 | ED8: 1 | EF8: =sum(CH8:ED8) -> 9 | EG8: =EF8*B8 -> 2961 | EM8: 1 | FR8: 1 | FX8: 1 | FZ8: 1 | GH8: =sum(EI8:GG8) -> 4 | GI8: =GH8*B8 -> 1316 | HG8: 1 | HM8: 1 | HQ8: 1 | HT8: 1 | HZ8: 1 | IO8: 1 | JR8: 1 | JX8: 2
A9: Mountain Breeze | B9: 329 | CE9: =sum(C9:CD9) -> 0 | CF9: =CE9*B9 -> 0 | EF9: =sum(CH9:ED9) -> 0 | EG9: =EF9*B9 -> 0 | GH9: =sum(EI9:GG9) -> 0 | GI9: =GH9*EA9 -> 0
A10: Fresh Bamboo | B10: 329 | C10: 1 | M10: 1 | P10: 2 | U10: 1 | AA10: 1 | AC10: 1 | AD10: 1 | AE10: 1 | AG10: 1 | AH10: 1 | AI10: 1 | AJ10: 1 | AL10: 1 | BK10: 1 | BP10: 1 | BR10: 1 | BS10: 1 | BZ10: 4 | CE10: =sum(C10:CD10) -> 22 | CF10: =CE10*B10 -> 7238 | CI10: 1 | CJ10: 1 | DI10: 1 | DK10: 1 | EF10: =sum(CH10:ED10) -> 4 | EG10: =EF10*B10 -> 1316 | EP10: 1 | EQ10: 1 | FD10: 1 | FI10: 1 | FP10: 1 | GH10: =sum(EI10:GG10) -> 5 | GI10: =GH10*B10 -> 1645 | GU10: 1 | HH10: 1 | HM10: 1 | HT10: 1 | II10: 1 | IY10: 1 | JA10: 1 | JH10: 1 | JJ10: 2 | JL10: 1 | JO10: 1 | JW10: 1 | JZ10: 1
A11: Beach Escape | B11: 329 | C11: 1 | CE11: =sum(C11:CD11) -> 1 | CF11: =CE11*B11 -> 329 | DS11: 1 | EF11: =sum(CH11:ED11) -> 1 | EG11: =EF11*B11 -> 329 | ER11: 1 | ES11: 1 | ET11: 1 | EU11: 1 | FT11: 2 | FV11: 1 | FX11: 1 | GH11: =sum(EI11:GG11) -> 8 | GI11: =GH11*B11 -> 2632 | GP11: 1 | GV11: 1 | HK11: 1 | HZ11: 1 | JM11: 2 | JU11: 1
A12: White Tea | B12: 329 | C12: 1 | I12: 1 | O12: 1 | AA12: 1 | AT12: 1 | AY12: 1 | BI12: 1 | BT12: 1 | BW12: 1 | BX12: 1 | CC12: 1 | CE12: =sum(C12:CD12) -> 11 | CF12: =CE12*B12 -> 3619 | CI12: 1 | CK12: 1 | CL12: 1 | CP12: 1 | CQ12: 1 | DZ12: 1 | EC12: 1 | EF12: =sum(CH12:ED12) -> 7 | EG12: =EF12*B12 -> 2303 | ER12: 1 | ET12: 1 | FL12: 2 | FX12: 1 | GC12: 1 | GH12: =sum(EI12:GG12) -> 6 | GI12: =GH12*B12 -> 1974 | GP12: 1 | GQ12: 1 | GS12: 1 | HR12: 1 | HU12: 2 | II12: 1 | IR12: 1 | IU12: 1 | IW12: 1 | JC12: 1 | JG12: 1 | JN12: 1 | JO12: 1
A13: Candy Cane | B13: 329 | G13: 1 | X13: 1 | AY13: 1 | CE13: =sum(C13:CD13) -> 3 | CF13: =CE13*B13 -> 987 | EF13: =sum(CH13:ED13) -> 0 | EG13: =EF13*B13 -> 0 | EZ13: 1 | FV13: 1 | GH13: =sum(EI13:GG13) -> 2 | GI13: =GH13*B13 -> 658 | GT13: 1
A14: Apple Cinnamon | B14: 329 | G14: 2 | Q14: 1 | AO14: 1 | CE14: =sum(C14:CD14) -> 4 | CF14: =CE14*B14 -> 1316 | DJ14: 2 | DW14: 1 | EF14: =sum(CH14:ED14) -> 3 | EG14: =EF14*B14 -> 987 | GH14: =sum(EI14:GG14) -> 0 | GI14: =GH14*B14 -> 0 | HH14: 1 | II14: 1 | IN14: 1 | IX14: 1
A15: Easy Drive | B15: 219 | AO15: 1 | CE15: =sum(C15:CD15) -> 1 | CF15: =CE15*B15 -> 219 | CR15: 1 | CT15: 1 | CW15: 1 | EF15: =sum(CH15:ED15) -> 3 | EG15: =EF15*B15 -> 657 | EL15: 2 | EW15: 1 | EZ15: 1 | GH15: =sum(EI15:GG15) -> 4 | GI15: =GH15*B15 -> 876 | IZ15: 1 | JY15: 1
A16: InLove | CE16: =sum(C16:CD16) -> 0 | CF16: =CE16*B16 -> 0 | EF16: =sum(CH16:ED16) -> 0 | EG16: =EF16*B16 -> 0 | GH16: =sum(EI16:GG16) -> 0 | GI16: =GH16*B16 -> 0
A17: Bright Mornings HW | CE17: =sum(C17:CD17) -> 0 | CF17: =CE17*B17 -> 0 | EF17: =sum(CH17:ED17) -> 0 | EG17: =EF17*B17 -> 0 | GH17: =sum(EI17:GG17) -> 0 | GI17: =GH17*B17 -> 0
CE18: =sum(C18:CD18) -> 0 | CF18: =CE18*B18 -> 0 | EF18: =sum(CH18:ED18) -> 0 | EG18: =EF18*B18 -> 0 | GH18: =sum(EI18:GG18) -> 0 | GI18: =GH18*B18 -> 0
A19: Lavender | B19: 239 | BR19: 1 | CE19: =sum(C19:CD19) -> 1 | CF19: =CE19*B19 -> 239 | EF19: =sum(CH19:ED19) -> 0 | EG19: =EF19*B19 -> 0 | GH19: =sum(EI19:GG19) -> 0 | GI19: =GH19*B19 -> 0
A20: Eucalyptus | B20: 239 | CE20: =sum(C20:CD20) -> 0 | CF20: =CE20*B20 -> 0 | EF20: =sum(CH20:ED20) -> 0 | EG20: =EF20*B20 -> 0 | GH20: =sum(EI20:GG20) -> 0 | GI20: =GH20*B20 -> 0
A21: Peppermint | B21: 239 | CE21: =sum(C21:CD21) -> 0 | CF21: =CE21*B21 -> 0 | DC21: 3 | EF21: =sum(CH21:ED21) -> 3 | EG21: =EF21*B21 -> 717 | GC21: 1 | GH21: =sum(EI21:GG21) -> 1 | GI21: =GH21*B21 -> 239
A22: Fresh Bamboo FO | B22: 219 | AU22: 1 | AV22: 1 | AZ22: 1 | CE22: =sum(C22:CD22) -> 3 | CF22: =CE22*B22 -> 657 | EF22: =sum(CH22:ED22) -> 0 | EG22: =EF22*B22 -> 0 | GH22: =sum(EI22:GG22) -> 0 | GI22: =GH22*B22 -> 0
A23: Beach Escape FO | B23: 219 | H23: p | AV23: 1 | CE23: =sum(C23:CD23) -> 1 | CF23: =CE23*B23 -> 219 | EF23: =sum(CH23:ED23) -> 0 | EG23: =EF23*B23 -> 0 | GH23: =sum(EI23:GG23) -> 0 | GI23: =GH23*B23 -> 0 | IQ23: 1
A24: White Tea FO | B24: 219 | CE24: =sum(C24:CD24) -> 0 | CF24: =CE24*B24 -> 0 | EF24: =sum(CH24:ED24) -> 0 | EG24: =EF24*B24 -> 0 | GH24: =sum(EI24:GG24) -> 0 | GI24: =GH24*B24 -> 0 | GY24: 1
A25: Bright Mornings FO | B25: 219 | CE25: =sum(C25:CD25) -> 0 | CF25: =CE25*B25 -> 0 | EF25: =sum(CH25:ED25) -> 0 | EG25: =EF25*B25 -> 0 | GH25: =sum(EI25:GG25) -> 0 | GI25: =GH25*B25 -> 0
A26: Quiet Elegance FO | B26: 219 | CE26: =sum(C26:CD26) -> 0 | CF26: =CE26*B26 -> 0 | EF26: =sum(CH26:ED26) -> 0 | EG26: =EF26*B26 -> 0 | GH26: =sum(EI26:GG26) -> 0 | GI26: =GH26*B26 -> 0
A27: Fresh Bamboo Diffuser | B27: 799 | W27: 1 | CE27: =sum(C27:CD27) -> 1 | CF27: =CE27*B27 -> 799 | EF27: =sum(CH27:ED27) -> 0 | EG27: =EF27*B27 -> 0 | GH27: =sum(EI27:GG27) -> 0 | GI27: =GH27*B27 -> 0 | JI27: 1
A28: Clean Air | B28: 609 | K28: 1 | AN28: 1 | AR28: 1 | BD28: 1 | CE28: =sum(C28:CD28) -> 4 | CF28: =CE28*B28 -> 2436 | DQ28: 1 | EE28: 1 | EF28: =sum(CH28:EE28) -> 2 | EG28: =EF28*B28 -> 1218 | FV28: 1 | GH28: =sum(EI28:GG28) -> 1 | GI28: =GH28*B28 -> 609 | GM28: 1 | GW28: 1 | HF28: 1 | HS28: 1 | HW28: 1 | IE28: 1 | IU28: 1 | JY28: 1
A29: Cotton Clean | B29: 329 | C29: 1 | D29: 1 | P29: 2 | T29: 1 | X29: 1 | Y29: 4 | AJ29: 1 | AQ29: 1 | AX29: 1 | AY29: 1 | BL29: 1 | BR29: 1 | BX29: 1 | CE29: =sum(C29:CD29) -> 17 | CF29: =CE29*B29 -> 5593 | CJ29: 1 | EF29: =sum(CH29:ED29) -> 1 | EG29: =EF29*B29 -> 329 | EN29: 1 | EO29: 2 | ES29: 1 | EU29: 1 | FA29: 1 | FI29: 1 | FK29: 1 | FW29: 1 | GB29: 1 | GH29: =sum(EI29:GG29) -> 10 | GI29: =GH29*B29 -> 3290 | GP29: 1 | HF29: 1 | HJ29: 3 | HS29: 1 | HY29: 1 | HZ29: 1 | IP29: 1 | JY29: 1
A30: Brighter Days | B30: 329 | CE30: =sum(C30:CD30) -> 0 | CF30: =CE30*B30 -> 0 | EF30: =sum(CH30:ED30) -> 0 | EG30: =EF30*B30 -> 0 | GH30: =sum(EI30:GG30) -> 0 | GI30: =GH30*B30 -> 0
A31: Cotton Clean FO | B31: 219 | CE31: =sum(C31:CD31) -> 0 | CF31: =CE31*B31 -> 0 | EF31: =sum(CH31:ED31) -> 0 | EG31: =EF31*B31 -> 0 | GH31: =sum(EI31:GG31) -> 0 | GI31: =GH31*B31 -> 0
A32: Brighter Days EO | B32: 219 | CE32: =sum(C32:CD32) -> 0 | CF32: =CE32*B32 -> 0 | EF32: =sum(CH32:ED32) -> 0 | EG32: =EF32*B32 -> 0 | GH32: =sum(EI32:GG32) -> 0 | GI32: =GH32*B32 -> 0
A33: Fresh Bamboo Refill | B33: 439 | BO33: 1 | CE33: =sum(C33:CD33) -> 1 | CF33: =CE33*B33 -> 439 | CV33: 1 | EF33: =sum(CH33:ED33) -> 1 | EG33: =EF33*B33 -> 439 | FB33: 1 | GH33: =sum(EI33:GG33) -> 1 | GI33: =GH33*B33 -> 439 | GZ33: 1 | IZ33: 1
A34: Clean Air Refill 1000ml | B34: 899 | CE34: =sum(C34:CD34) -> 0 | CF34: =CE34*B34 -> 0 | EF34: =sum(CH34:ED34) -> 0 | EG34: =EF34*B34 -> 0 | GH34: =sum(EI34:GG34) -> 0 | GI34: =GH34*B34 -> 0
A35: Waterbased: Fresh Bamboo | B35: 549 | CE35: =sum(C35:CD35) -> 0 | CF35: =CE35*B35 -> 0 | EF35: =sum(CH35:ED35) -> 0 | EG35: =EF35*B35 -> 0 | GH35: =sum(EI35:GG35) -> 0 | GI35: =GH35*B35 -> 0 | JB35: 1
A36: Waterbased: Cotton Clean | B36: 549 | CE36: =sum(C36:CD36) -> 0 | CF36: =CE36*B36 -> 0 | EF36: =sum(CH36:ED36) -> 0 | EG36: =EF36*B36 -> 0 | EV36: 1 | GH36: =sum(EI36:GG36) -> 1 | GI36: =GH36*B36 -> 549
A37: Waterbased: White Tea | B37: 549 | O37: 1 | V37: 1 | CE37: =sum(C37:CD37) -> 2 | CF37: =CE37*B37 -> 1098 | EF37: =sum(CH37:ED37) -> 0 | EG37: =EF37*B37 -> 0 | FH37: 1 | GH37: =sum(EI37:GG37) -> 1 | GI37: =GH37*B37 -> 549
A38: White Tea Diffuser | B38: 799 | CE38: =sum(C38:CD38) -> 0 | CF38: =CE38*B38 -> 0 | DV38: 1 | EF38: =sum(CH38:ED38) -> 1 | EG38: =EF38*B38 -> 799 | FU38: 1 | GH38: =sum(EI38:GG38) -> 1 | GI38: =GH38*B38 -> 799
A39: Cotton Clean Diffuser | B39: 799 | CE39: =sum(C39:CD39) -> 0 | CF39: =CE39*B39 -> 0 | CV39: 1 | EF39: =sum(CH39:ED39) -> 1 | EG39: =EF39*B39 -> 799 | GH39: =sum(EI39:GG39) -> 0 | GI39: =GH39*B39 -> 0
A40: White Tea Diffuser Refill | B40: 439 | V40: 1 | AS40: 1 | CC40: 1 | CE40: =sum(C40:CD40) -> 3 | CF40: =CE40*B40 -> 1317 | EF40: =sum(CH40:ED40) -> 0 | EG40: =EF40*B40 -> 0 | FB40: 1 | GH40: =sum(EI40:GG40) -> 1 | GI40: =GH40*B40 -> 439 | IV40: 3
A41: Cotton Clean Diffuser Refill | B41: 439 | BC41: 2 | BO41: 1 | CE41: =sum(C41:CD41) -> 3 | CF41: =CE41*B41 -> 1317 | EF41: =sum(CH41:ED41) -> 0 | EG41: =EF41*B41 -> 0 | FB41: 1 | GH41: =sum(EI41:GG41) -> 1 | GI41: =GH41*B41 -> 439
...

Sheet SHOPIFY
X2: april | AH2: MAY
